Workbook

Sheet RECHERCHE
B6: UN : | C6: 3082
B7: POIDS : | C7: 1000
B8: A/D/I : | C8: =IF(C7="","",IF(VLOOKUP(RECHERCHE!C6,'CODE UN VS CODE H'!$A$1:$AZ$2322,50,FALSE)<RECHERCHE!C7,"Interdit",IF(C7="","",VLOOKUP(C6,'CODE UN VS CODE H'!$A$1:$AH$50000,34,FALSE)))) -> Accepted
B9: ICPE : | C9: =IF(C8="","",VLOOKUP(C6,'CODE UN VS CODE H'!$A$1:$AZ$2322,52,FALSE)) -> 4511

Sheet Sheet1

Sheet Sheet2

Sheet CODE H VS CODE ICPE
A1: Code Mention de danger | B1: Signification des mentions | C1: Rubrique ICPE | D1: Stockage | E1: STOCK MAX | G1: ok / ko
A2: H300 | B2: Mortel en cas d’ingestion. | C2: 4110 | D2: Demande d'autorisation | E2: 199.99 | G2: =IF(C2="","ko","ok") -> ok
A3: H310 | B3: Mortel par contact cutané. | C3: 4110 | D3: Interdit | E3: 199.99 | G3: =IF(C3="","ko","ok") -> ok
A4: H311 | B4: Toxique par contact cutané. | C4: 4110 | D4: Demande d'autorisation | E4: 199.99 | G4: =IF(C4="","ko","ok") -> ok
A5: H312 | B5: Nocif par contact cutané. | C5: 4110 | D5: Demande d'autorisation | E5: 199.99 | G5: =IF(C5="","ko","ok") -> ok
A6: H330 | B6: Mortel par inhalation. | C6: 4110 | D6: Interdit | E6: 199.99 | G6: =IF(C6="","ko","ok") -> ok
A7: H370 | B7: Risque avéré d’effets graves pour les organes <ou indiquer tous les organes affectés, s’ils sont connus> <indiquer la voie d’exposition s’il est formellement prouvé qu’aucune autre voie d’exposition ne conduit au même danger>. | C7: 4150 | D7: Demande d'autorisation | E7: 4999.99 | G7: =IF(C7="","ko","ok") -> ok
A8: H200 | B8: Explosif instable. | C8: 4210 | D8: Interdit | E8: 99.99 | G8: =IF(C8="","ko","ok") -> ok
A9: H201 | B9: Explosif ; danger d’explosion en masse. | C9: 4210 | D9: Interdit | E9: 99.99 | G9: =IF(C9="","ko","ok") -> ok
A10: H202 | B10: Explosif ; danger d’explosion en masse. | C10: 4210 | D10: Interdit | E10: 99.99 | G10: =IF(C10="","ko","ok") -> ok
A11: H203 | B11: Explosif; danger d’incendie, d’effet de souffle ou de projection. | C11: 4210 | D11: Interdit | E11: 99.99 | G11: =IF(C11="","ko","ok") -> ok
A12: H204 | B12: Danger d’incendie ou de projection. | C12: 4210 | D12: Demande d'autorisation | E12: 99.99 | G12: =IF(C12="","ko","ok") -> ok
A13: H205 | B13: Danger d’explosion en masse en cas d’incendie. | C13: 4210 | D13: Interdit | E13: 99.99 | G13: =IF(C13="","ko","ok") -> ok
... A80: H420 | B80: Nuit à la santé publique et à l’environnement en détruisant l’ozone dans la haute atmosphère. | C80: 4710 | D80: Interdit | E80: 99.99 | G80: =IF(C80="","ko","ok") -> ok

Sheet CODE UN VS CODE H
A1: N° ONU | B1: Nom et description | C1: Classe | D1: Code de Classification | E1: Name and description | F1: CODE H 1 : | G1: CODE H 2 : | H1: CODE H 3 : | I1: CODE H 4 : | J1: CODE H 5 : | K1: CODE H 6 : | L1: CODE H 7 : | M1: CODE H 8 : | N1: CODE H 9 : | O1: CODE H 10 : | P1: CODE H 11 : | Q1: CODE H 12 : | R1: CODE H 13 : | S1: CODE H 14 : | T1: A/D/I CODE H 1 | U1: A/D/I CODE H 2 | V1: A/D/I CODE H 3 | W1: A/D/I CODE H 4 | X1: A/D/I CODE H 5 | Y1: A/D/I CODE H 6 | Z1: A/D/I CODE H 7 | AA1: A/D/I CODE H 8 | AB1: A/D/I CODE H 9 | AC1: A/D/I CODE H 10 | AD1: A/D/I CODE H 11 | AE1: A/D/I CODE H 12 | AF1: A/D/I CODE H 13 | AG1: A/D/I CODE H 14 | AH1: RESULTAT | AI1: POIDS MAX CODE H 1 | AJ1: POIDS MAX CODE H 2 | AK1: POIDS MAX CODE H 3 | AL1: POIDS MAX CODE H 4 | AM1: POIDS MAX CODE H 5 | AN1: POIDS MAX CODE H 6 | AO1: POIDS MAX CODE H 7 | AP1: POIDS MAX CODE H 8 | AQ1: POIDS MAX CODE H 9 | AR1: POIDS MAX CODE H 10 | AS1: POIDS MAX CODE H 11 | AT1: POIDS MAX CODE H 12 | AU1: POIDS MAX CODE H 13 | AV1: POIDS MAX CODE H 14 | AW1: RESULTAT | AX1: POIDS MAX UN | AY1: DERNIER CODE VS CLASS ICPE | AZ1: CLASSE ICPE
A2: 1648 | B2: ACÉTONITRILE | C2: 6.1 | D2: T1 | E2: METHYL BROMIDE AND ETHYLENE DIBROMIDE MIXTURE, LIQUID | F2: H225 | G2: h302 | H2: h312 | I2: h332 | J2: h319 | T2: =IFERROR(VLOOKUP(F2,'CODE H VS CODE ICPE'!$A$2:$D$80,4,FALSE),"") -> Autorisé | U2: =IFERROR(VLOOKUP(G2,'CODE H VS CODE ICPE'!$A$2:$D$80,4,FALSE),"") -> Autorisé | V2: =IFERROR(VLOOKUP(H2,'CODE H VS CODE ICPE'!$A$2:$D$80,4,FALSE),"") -> Demande d'autorisation | W2: =IFERROR(VLOOKUP(I2,'CODE H VS CODE ICPE'!$A$2:$D$80,4,FALSE),"") -> Interdit | X2: =IFERROR(VLOOKUP(J2,'CODE H VS CODE ICPE'!$A$2:$D$80,4,FALSE),"") -> Autorisé | Y2: =IFERROR(VLOOKUP(K2,'CODE H VS CODE ICPE'!$A$2:$D$80,4,FALSE),"") | Z2: =IFERROR(VLOOKUP(L2,'CODE H VS CODE ICPE'!$A$2:$D$80,4,FALSE),"") | AA2: =IFERROR(VLOOKUP(M2,'CODE H VS CODE ICPE'!$A$2:$D$80,4,FALSE),"") | ... AG2: =IFERROR(VLOOKUP(S2,'CODE H VS CODE ICPE'!$A$2:$D$80,4,FALSE),"") | AH2: Accepted | AI2: =IF(T2="",0,IF(T2="Interdit",0,VLOOKUP(F2,'CODE H VS CODE ICPE'!$A$2:$E$80,5,FALSE))) -> 99999.99 | AJ2: =IF(U2="",0,IF(U2="Interdit",0,VLOOKUP(G2,'CODE H VS CODE ICPE'!$A$2:$E$80,5,FALSE))) -> 99999.99 | AK2: =IF(V2="",0,IF(V2="Interdit",0,VLOOKUP(H2,'CODE H VS CODE ICPE'!$A$2:$E$80,5,FALSE))) -> 199.99 | AL2: =IF(W2="",0,IF(W2="Interdit",0,VLOOKUP(I2,'CODE H VS CODE ICPE'!$A$2:$E$80,5,FALSE))) -> 0 | AM2: =IF(X2="",0,IF(X2="Interdit",0,VLOOKUP(J2,'CODE H VS CODE ICPE'!$A$2:$E$80,5,FALSE))) -> 99999.99 | AN2: =IF(Y2="",0,IF(Y2="Interdit",0,VLOOKUP(K2,'CODE H VS CODE ICPE'!$A$2:$E$80,5,FALSE))) -> 0 | AO2: =IF(Z2="",0,IF(Z2="Interdit",0,VLOOKUP(L2,'CODE H VS CODE ICPE'!$A$2:$E$80,5,FALSE))) -> 0 | AP2: =IF(AA2="",0,IF(AA2="Interdit",0,VLOOKUP(M2,'CODE H VS CODE ICPE'!$A$2:$E$80,5,FALSE))) -> 0 | ... AV2: =IF(AG2="",0,IF(AG2="Interdit",0,VLOOKUP(S2,'CODE H VS CODE ICPE'!$A$2:$E$80,5,FALSE))) -> 0 | AW2: =ADDRESS(2,MATCH(MAX(AI2:AV2),AI2:AV2,0)+COLUMN(AI2)-1) -> $AI$2 | AX2: =IF(AH2="Interdit","",IF(AW2="$AI$2",AI2,IF(AW2="$AJ$2",AJ2,IF(AW2="$AK$2",AK2,IF(AW2="$AL$2",AL2,IF(AW2="$AM$2",AM2,IF(AW2="$AN$2",AN2,IF(AW2="$AO$2",AO2,IF(AW2="$AP$2",AP2,IF(AW2="$AQ$2",AQ2,IF(AW2="$AR$2",AR2,IF(AW2="$AS$2",AS2,IF(AW2="$AT$2",AT2,IF(AW2="$AU$2",AU2,IF(AW2="$AV$2",AV2,""))))))))))))))) -> 99999.99 | AY2: =IF(AX2="","",IF(AW2="$AI$2",F2,IF(AW2="$AJ$2",G2,IF(AW2="$AK$2",H2,IF(AW2="$AL$2",I2,IF(AW2="$AM$2",J2,IF(AW2="$AN$2",K2,IF(AW2="$AO$2",L2,IF(AW2="$AP$2",M2,IF(AW2="$AQ$2",N2,IF(AW2="$AR$2",O2,IF(AW2="$AS$2",P2,IF(AW2="$AT$2",Q2,IF(AW2="$AU$2",R2,IF(AW2="$AV$2",S2,""))))))))))))))) -> H225 | AZ2: =IF(AY2="","",IF(AY2=0,"",VLOOKUP(AY2,'CODE H VS CODE ICPE'!$A$1:$E$80,3,FALSE))) -> 4331
A3: 1065 | B3: NÉON COMPRIMÉ | C3: 2 | D3: 1A | E3: NEON, COMPRESSED | F3: H222 | G3: H229 | H3: H319 | I3: H336 | T3: =IFERROR(VLOOKUP(F3,'CODE H VS CODE ICPE'!$A$2:$D$80,4,FALSE),"") -> Autorisé | U3: =IFERROR(VLOOKUP(G3,'CODE H VS CODE ICPE'!$A$2:$D$80,4,FALSE),"") -> Autorisé | V3: =IFERROR(VLOOKUP(H3,'CODE H VS CODE ICPE'!$A$2:$D$80,4,FALSE),"") -> Autorisé | W3: =IFERROR(VLOOKUP(I3,'CODE H VS CODE ICPE'!$A$2:$D$80,4,FALSE),"") -> Autorisé | X3: =IFERROR(VLOOKUP(J3,'CODE H VS CODE ICPE'!$A$2:$D$80,4,FALSE),"") | Y3: =IFERROR(VLOOKUP(K3,'CODE H VS CODE ICPE'!$A$2:$D$80,4,FALSE),"") | Z3: =IFERROR(VLOOKUP(L3,'CODE H VS CODE ICPE'!$A$2:$D$80,4,FALSE),"") | AA3: =IFERROR(VLOOKUP(M3,'CODE H VS CODE ICPE'!$A$2:$D$80,4,FALSE),"") | ... AG3: =IFERROR(VLOOKUP(S3,'CODE H VS CODE ICPE'!$A$2:$D$80,4,FALSE),"") | AH3: =IF(COUNTIF(T3:AG3, "Rejected") > 0, "Rejected", IF(COUNTIF(T3:AG3, "Under request") > 0, "Under request", "Accepted")) -> Accepted | AI3: =IF(T3="",0,IF(T3="Interdit",0,VLOOKUP(F3,'CODE H VS CODE ICPE'!$A$2:$E$80,5,FALSE))) -> 149999.99 | AJ3: =IF(U3="",0,IF(U3="Interdit",0,VLOOKUP(G3,'CODE H VS CODE ICPE'!$A$2:$E$80,5,FALSE))) -> 149999.99 | AK3: =IF(V3="",0,IF(V3="Interdit",0,VLOOKUP(H3,'CODE H VS CODE ICPE'!$A$2:$E$80,5,FALSE))) -> 99999.99 | AL3: =IF(W3="",0,IF(W3="Interdit",0,VLOOKUP(I3,'CODE H VS CODE ICPE'!$A$2:$E$80,5,FALSE))) -> 99999.99 | AM3: =IF(X3="",0,IF(X3="Interdit",0,VLOOKUP(J3,'CODE H VS CODE ICPE'!$A$2:$E$80,5,FALSE))) -> 0 | AN3: =IF(Y3="",0,IF(Y3="Interdit",0,VLOOKUP(K3,'CODE H VS CODE ICPE'!$A$2:$E$80,5,FALSE))) -> 0 | AO3: =IF(Z3="",0,IF(Z3="Interdit",0,VLOOKUP(L3,'CODE H VS CODE ICPE'!$A$2:$E$80,5,FALSE))) -> 0 | AP3: =IF(AA3="",0,IF(AA3="Interdit",0,VLOOKUP(M3,'CODE H VS CODE ICPE'!$A$2:$E$80,5,FALSE))) -> 0 | ... AV3: =IF(AG3="",0,IF(AG3="Interdit",0,VLOOKUP(S3,'CODE H VS CODE ICPE'!$A$2:$E$80,5,FALSE))) -> 0 | AW3: =ADDRESS(2,MATCH(MAX(AI3:AV3),AI3:AV3,0)+COLUMN(AI3)-1) -> $AI$2 | AX3: =IF(AH3="Interdit","",IF(AW3="$AI$2",AI3,IF(AW3="$AJ$2",AJ3,IF(AW3="$AK$2",AK3,IF(AW3="$AL$2",AL3,IF(AW3="$AM$2",AM3,IF(AW3="$AN$2",AN3,IF(AW3="$AO$2",AO3,IF(AW3="$AP$2",AP3,IF(AW3="$AQ$2",AQ3,IF(AW3="$AR$2",AR3,IF(AW3="$AS$2",AS3,IF(AW3="$AT$2",AT3,IF(AW3="$AU$2",AU3,IF(AW3="$AV$2",AV3,""))))))))))))))) -> 149999.99 | AY3: =IF(AX3="","",IF(AW3="$AI$2",F3,IF(AW3="$AJ$2",G3,IF(AW3="$AK$2",H3,IF(AW3="$AL$2",I3,IF(AW3="$AM$2",J3,IF(AW3="$AN$2",K3,IF(AW3="$AO$2",L3,IF(AW3="$AP$2",M3,IF(AW3="$AQ$2",N3,IF(AW3="$AR$2",O3,IF(AW3="$AS$2",P3,IF(AW3="$AT$2",Q3,IF(AW3="$AU$2",R3,IF(AW3="$AV$2",S3,""))))))))))))))) -> H222 | AZ3: =IF(AY3="","",IF(AY3=0,"",VLOOKUP(AY3,'CODE H VS CODE ICPE'!$A$1:$E$80,3,FALSE))) -> 4320
A4: 1090 | B4: ACÉTONE | C4: 3 | D4: F1 | E4: ACETONE | F4: H225 | G4: H319 | H4: H336 | T4: =IFERROR(VLOOKUP(F4,'CODE H VS CODE ICPE'!$A$2:$D$80,4,FALSE),"") -> Autorisé | U4: =IFERROR(VLOOKUP(G4,'CODE H VS CODE ICPE'!$A$2:$D$80,4,FALSE),"") -> Autorisé | V4: =IFERROR(VLOOKUP(H4,'CODE H VS CODE ICPE'!$A$2:$D$80,4,FALSE),"") -> Autorisé | W4: =IFERROR(VLOOKUP(I4,'CODE H VS CODE ICPE'!$A$2:$D$80,4,FALSE),"") | X4: =IFERROR(VLOOKUP(J4,'CODE H VS CODE ICPE'!$A$2:$D$80,4,FALSE),"") | Y4: =IFERROR(VLOOKUP(K4,'CODE H VS CODE ICPE'!$A$2:$D$80,4,FALSE),"") | Z4: =IFERROR(VLOOKUP(L4,'CODE H VS CODE ICPE'!$A$2:$D$80,4,FALSE),"") | AA4: =IFERROR(VLOOKUP(M4,'CODE H VS CODE ICPE'!$A$2:$D$80,4,FALSE),"") | ... AG4: =IFERROR(VLOOKUP(S4,'CODE H VS CODE ICPE'!$A$2:$D$80,4,FALSE),"") | AH4: =IF(COUNTIF(T4:AG4, "Rejected") > 0, "Rejected", IF(COUNTIF(T4:AG4, "Under request") > 0, "Under request", "Accepted")) -> Accepted | AI4: =IF(T4="",0,IF(T4="Interdit",0,VLOOKUP(F4,'CODE H VS CODE ICPE'!$A$2:$E$80,5,FALSE))) -> 99999.99 | AJ4: =IF(U4="",0,IF(U4="Interdit",0,VLOOKUP(G4,'CODE H VS CODE ICPE'!$A$2:$E$80,5,FALSE))) -> 99999.99 | AK4: =IF(V4="",0,IF(V4="Interdit",0,VLOOKUP(H4,'CODE H VS CODE ICPE'!$A$2:$E$80,5,FALSE))) -> 99999.99 | AL4: =IF(W4="",0,IF(W4="Interdit",0,VLOOKUP(I4,'CODE H VS CODE ICPE'!$A$2:$E$80,5,FALSE))) -> 0 | AM4: =IF(X4="",0,IF(X4="Interdit",0,VLOOKUP(J4,'CODE H VS CODE ICPE'!$A$2:$E$80,5,FALSE))) -> 0 | AN4: =IF(Y4="",0,IF(Y4="Interdit",0,VLOOKUP(K4,'CODE H VS CODE ICPE'!$A$2:$E$80,5,FALSE))) -> 0 | AO4: =IF(Z4="",0,IF(Z4="Interdit",0,VLOOKUP(L4,'CODE H VS CODE ICPE'!$A$2:$E$80,5,FALSE))) -> 0 | AP4: =IF(AA4="",0,IF(AA4="Interdit",0,VLOOKUP(M4,'CODE H VS CODE ICPE'!$A$2:$E$80,5,FALSE))) -> 0 | ... AV4: =IF(AG4="",0,IF(AG4="Interdit",0,VLOOKUP(S4,'CODE H VS CODE ICPE'!$A$2:$E$80,5,FALSE))) -> 0 | AW4: =ADDRESS(2,MATCH(MAX(AI4:AV4),AI4:AV4,0)+COLUMN(AI4)-1) -> $AI$2 | AX4: =IF(AH4="Interdit","",IF(AW4="$AI$2",AI4,IF(AW4="$AJ$2",AJ4,IF(AW4="$AK$2",AK4,IF(AW4="$AL$2",AL4,IF(AW4="$AM$2",AM4,IF(AW4="$AN$2",AN4,IF(AW4="$AO$2",AO4,IF(AW4="$AP$2",AP4,IF(AW4="$AQ$2",AQ4,IF(AW4="$AR$2",AR4,IF(AW4="$AS$2",AS4,IF(AW4="$AT$2",AT4,IF(AW4="$AU$2",AU4,IF(AW4="$AV$2",AV4,""))))))))))))))) -> 99999.99 | AY4: =IF(AX4="","",IF(AW4="$AI$2",F4,IF(AW4="$AJ$2",G4,IF(AW4="$AK$2",H4,IF(AW4="$AL$2",I4,IF(AW4="$AM$2",J4,IF(AW4="$AN$2",K4,IF(AW4="$AO$2",L4,IF(AW4="$AP$2",M4,IF(AW4="$AQ$2",N4,IF(AW4="$AR$2",O4,IF(AW4="$AS$2",P4,IF(AW4="$AT$2",Q4,IF(AW4="$AU$2",R4,IF(AW4="$AV$2",S4,""))))))))))))))) -> H225 | AZ4: =IF(AY4="","",IF(AY4=0,"",VLOOKUP(AY4,'CODE H VS CODE ICPE'!$A$1:$E$80,3,FALSE))) -> 4331
A5: 1107 | B5: CHLORURES D'AMYLE | C5: 3 | D5: F1 | E5: AMYL CHLORIDE | F5: H314 | T5: =IFERROR(VLOOKUP(F5,'CODE H VS CODE ICPE'!$A$2:$D$80,4,FALSE),"") -> Autorisé | U5: =IFERROR(VLOOKUP(G5,'CODE H VS CODE ICPE'!$A$2:$D$80,4,FALSE),"") | V5: =IFERROR(VLOOKUP(H5,'CODE H VS CODE ICPE'!$A$2:$D$80,4,FALSE),"") | W5: =IFERROR(VLOOKUP(I5,'CODE H VS CODE ICPE'!$A$2:$D$80,4,FALSE),"") | X5: =IFERROR(VLOOKUP(J5,'CODE H VS CODE ICPE'!$A$2:$D$80,4,FALSE),"") | Y5: =IFERROR(VLOOKUP(K5,'CODE H VS CODE ICPE'!$A$2:$D$80,4,FALSE),"") | Z5: =IFERROR(VLOOKUP(L5,'CODE H VS CODE ICPE'!$A$2:$D$80,4,FALSE),"") | AA5: =IFERROR(VLOOKUP(M5,'CODE H VS CODE ICPE'!$A$2:$D$80,4,FALSE),"") | ... AG5: =IFERROR(VLOOKUP(S5,'CODE H VS CODE ICPE'!$A$2:$D$80,4,FALSE),"") | AH5: =IF(COUNTIF(T5:AG5, "Rejected") > 0, "Rejected", IF(COUNTIF(T5:AG5, "Under request") > 0, "Under request", "Accepted")) -> Accepted | AI5: =IF(T5="",0,IF(T5="Interdit",0,VLOOKUP(F5,'CODE H VS CODE ICPE'!$A$2:$E$80,5,FALSE))) -> 149999.99 | AJ5: =IF(U5="",0,IF(U5="Interdit",0,VLOOKUP(G5,'CODE H VS CODE ICPE'!$A$2:$E$80,5,FALSE))) -> 0 | AK5: =IF(V5="",0,IF(V5="Interdit",0,VLOOKUP(H5,'CODE H VS CODE ICPE'!$A$2:$E$80,5,FALSE))) -> 0 | AL5: =IF(W5="",0,IF(W5="Interdit",0,VLOOKUP(I5,'CODE H VS CODE ICPE'!$A$2:$E$80,5,FALSE))) -> 0 | AM5: =IF(X5="",0,IF(X5="Interdit",0,VLOOKUP(J5,'CODE H VS CODE ICPE'!$A$2:$E$80,5,FALSE))) -> 0 | AN5: =IF(Y5="",0,IF(Y5="Interdit",0,VLOOKUP(K5,'CODE H VS CODE ICPE'!$A$2:$E$80,5,FALSE))) -> 0 | AO5: =IF(Z5="",0,IF(Z5="Interdit",0,VLOOKUP(L5,'CODE H VS CODE ICPE'!$A$2:$E$80,5,FALSE))) -> 0 | AP5: =IF(AA5="",0,IF(AA5="Interdit",0,VLOOKUP(M5,'CODE H VS CODE ICPE'!$A$2:$E$80,5,FALSE))) -> 0 | ... AV5: =IF(AG5="",0,IF(AG5="Interdit",0,VLOOKUP(S5,'CODE H VS CODE ICPE'!$A$2:$E$80,5,FALSE))) -> 0 | AW5: =ADDRESS(2,MATCH(MAX(AI5:AV5),AI5:AV5,0)+COLUMN(AI5)-1) -> $AI$2 | AX5: =IF(AH5="Interdit","",IF(AW5="$AI$2",AI5,IF(AW5="$AJ$2",AJ5,IF(AW5="$AK$2",AK5,IF(AW5="$AL$2",AL5,IF(AW5="$AM$2",AM5,IF(AW5="$AN$2",AN5,IF(AW5="$AO$2",AO5,IF(AW5="$AP$2",AP5,IF(AW5="$AQ$2",AQ5,IF(AW5="$AR$2",AR5,IF(AW5="$AS$2",AS5,IF(AW5="$AT$2",AT5,IF(AW5="$AU$2",AU5,IF(AW5="$AV$2",AV5,""))))))))))))))) -> 149999.99 | AY5: =IF(AX5="","",IF(AW5="$AI$2",F5,IF(AW5="$AJ$2",G5,IF(AW5="$AK$2",H5,IF(AW5="$AL$2",I5,IF(AW5="$AM$2",J5,IF(AW5="$AN$2",K5,IF(AW5="$AO$2",L5,IF(AW5="$AP$2",M5,IF(AW5="$AQ$2",N5,IF(AW5="$AR$2",O5,IF(AW5="$AS$2",P5,IF(AW5="$AT$2",Q5,IF(AW5="$AU$2",R5,IF(AW5="$AV$2",S5,""))))))))))))))) -> H314 | AZ5: =IF(AY5="","",IF(AY5=0,"",VLOOKUP(AY5,'CODE H VS CODE ICPE'!$A$1:$E$80,3,FALSE))) -> 4320
A6: 1123 | B6: ACÉTATES DE BUTYLE | C6: 3 | D6: F1 | E6: BUTYL ACETATES | F6: H226 | G6: H336 | T6: =IFERROR(VLOOKUP(F6,'CODE H VS CODE ICPE'!$A$2:$D$80,4,FALSE),"") -> Autorisé | U6: =IFERROR(VLOOKUP(G6,'CODE H VS CODE ICPE'!$A$2:$D$80,4,FALSE),"") -> Autorisé | V6: =IFERROR(VLOOKUP(H6,'CODE H VS CODE ICPE'!$A$2:$D$80,4,FALSE),"") | W6: =IFERROR(VLOOKUP(I6,'CODE H VS CODE ICPE'!$A$2:$D$80,4,FALSE),"") | X6: =IFERROR(VLOOKUP(J6,'CODE H VS CODE ICPE'!$A$2:$D$80,4,FALSE),"") | Y6: =IFERROR(VLOOKUP(K6,'CODE H VS CODE ICPE'!$A$2:$D$80,4,FALSE),"") | Z6: =IFERROR(VLOOKUP(L6,'CODE H VS CODE ICPE'!$A$2:$D$80,4,FALSE),"") | AA6: =IFERROR(VLOOKUP(M6,'CODE H VS CODE ICPE'!$A$2:$D$80,4,FALSE),"") | ... AG6: =IFERROR(VLOOKUP(S6,'CODE H VS CODE ICPE'!$A$2:$D$80,4,FALSE),"") | AH6: =IF(COUNTIF(T6:AG6, "Rejected") > 0, "Rejected", IF(COUNTIF(T6:AG6, "Under request") > 0, "Under request", "Accepted")) -> Accepted | AI6: =IF(T6="",0,IF(T6="Interdit",0,VLOOKUP(F6,'CODE H VS CODE ICPE'!$A$2:$E$80,5,FALSE))) -> 99999.99 | AJ6: =IF(U6="",0,IF(U6="Interdit",0,VLOOKUP(G6,'CODE H VS CODE ICPE'!$A$2:$E$80,5,FALSE))) -> 99999.99 | AK6: =IF(V6="",0,IF(V6="Interdit",0,VLOOKUP(H6,'CODE H VS CODE ICPE'!$A$2:$E$80,5,FALSE))) -> 0 | AL6: =IF(W6="",0,IF(W6="Interdit",0,VLOOKUP(I6,'CODE H VS CODE ICPE'!$A$2:$E$80,5,FALSE))) -> 0 | AM6: =IF(X6="",0,IF(X6="Interdit",0,VLOOKUP(J6,'CODE H VS CODE ICPE'!$A$2:$E$80,5,FALSE))) -> 0 | AN6: =IF(Y6="",0,IF(Y6="Interdit",0,VLOOKUP(K6,'CODE H VS CODE ICPE'!$A$2:$E$80,5,FALSE))) -> 0 | AO6: =IF(Z6="",0,IF(Z6="Interdit",0,VLOOKUP(L6,'CODE H VS CODE ICPE'!$A$2:$E$80,5,FALSE))) -> 0 | AP6: =IF(AA6="",0,IF(AA6="Interdit",0,VLOOKUP(M6,'CODE H VS CODE ICPE'!$A$2:$E$80,5,FALSE))) -> 0 | ... AV6: =IF(AG6="",0,IF(AG6="Interdit",0,VLOOKUP(S6,'CODE H VS CODE ICPE'!$A$2:$E$80,5,FALSE))) -> 0 | AW6: =ADDRESS(2,MATCH(MAX(AI6:AV6),AI6:AV6,0)+COLUMN(AI6)-1) -> $AI$2 | AX6: =IF(AH6="Interdit","",IF(AW6="$AI$2",AI6,IF(AW6="$AJ$2",AJ6,IF(AW6="$AK$2",AK6,IF(AW6="$AL$2",AL6,IF(AW6="$AM$2",AM6,IF(AW6="$AN$2",AN6,IF(AW6="$AO$2",AO6,IF(AW6="$AP$2",AP6,IF(AW6="$AQ$2",AQ6,IF(AW6="$AR$2",AR6,IF(AW6="$AS$2",AS6,IF(AW6="$AT$2",AT6,IF(AW6="$AU$2",AU6,IF(AW6="$AV$2",AV6,""))))))))))))))) -> 99999.99 | AY6: =IF(AX6="","",IF(AW6="$AI$2",F6,IF(AW6="$AJ$2",G6,IF(AW6="$AK$2",H6,IF(AW6="$AL$2",I6,IF(AW6="$AM$2",J6,IF(AW6="$AN$2",K6,IF(AW6="$AO$2",L6,IF(AW6="$AP$2",M6,IF(AW6="$AQ$2",N6,IF(AW6="$AR$2",O6,IF(AW6="$AS$2",P6,IF(AW6="$AT$2",Q6,IF(AW6="$AU$2",R6,IF(AW6="$AV$2",S6,""))))))))))))))) -> H226 | AZ6: =IF(AY6="","",IF(AY6=0,"",VLOOKUP(AY6,'CODE H VS CODE ICPE'!$A$1:$E$80,3,FALSE))) -> 4331
A7: 1128 | B7: FORMIATE DE n-BUTYLE | C7: 3 | D7: F1 | E7: n-BUTYL FORMATE | F7: H225 | G7: H319 | H7: H335 | T7: =IFERROR(VLOOKUP(F7,'CODE H VS CODE ICPE'!$A$2:$D$80,4,FALSE),"") -> Autorisé | U7: =IFERROR(VLOOKUP(G7,'CODE H VS CODE ICPE'!$A$2:$D$80,4,FALSE),"") -> Autorisé | V7: =IFERROR(VLOOKUP(H7,'CODE H VS CODE ICPE'!$A$2:$D$80,4,FALSE),"") -> Autorisé | W7: =IFERROR(VLOOKUP(I7,'CODE H VS CODE ICPE'!$A$2:$D$80,4,FALSE),"") | X7: =IFERROR(VLOOKUP(J7,'CODE H VS CODE ICPE'!$A$2:$D$80,4,FALSE),"") | Y7: =IFERROR(VLOOKUP(K7,'CODE H VS CODE ICPE'!$A$2:$D$80,4,FALSE),"") | Z7: =IFERROR(VLOOKUP(L7,'CODE H VS CODE ICPE'!$A$2:$D$80,4,FALSE),"") | AA7: =IFERROR(VLOOKUP(M7,'CODE H VS CODE ICPE'!$A$2:$D$80,4,FALSE),"") | ... AG7: =IFERROR(VLOOKUP(S7,'CODE H VS CODE ICPE'!$A$2:$D$80,4,FALSE),"") | AH7: =IF(COUNTIF(T7:AG7, "Rejected") > 0, "Rejected", IF(COUNTIF(T7:AG7, "Under request") > 0, "Under request", "Accepted")) -> Accepted | AI7: =IF(T7="",0,IF(T7="Interdit",0,VLOOKUP(F7,'CODE H VS CODE ICPE'!$A$2:$E$80,5,FALSE))) -> 99999.99 | AJ7: =IF(U7="",0,IF(U7="Interdit",0,VLOOKUP(G7,'CODE H VS CODE ICPE'!$A$2:$E$80,5,FALSE))) -> 99999.99 | AK7: =IF(V7="",0,IF(V7="Interdit",0,VLOOKUP(H7,'CODE H VS CODE ICPE'!$A$2:$E$80,5,FALSE))) -> 99999.99 | AL7: =IF(W7="",0,IF(W7="Interdit",0,VLOOKUP(I7,'CODE H VS CODE ICPE'!$A$2:$E$80,5,FALSE))) -> 0 | AM7: =IF(X7="",0,IF(X7="Interdit",0,VLOOKUP(J7,'CODE H VS CODE ICPE'!$A$2:$E$80,5,FALSE))) -> 0 | AN7: =IF(Y7="",0,IF(Y7="Interdit",0,VLOOKUP(K7,'CODE H VS CODE ICPE'!$A$2:$E$80,5,FALSE))) -> 0 | AO7: =IF(Z7="",0,IF(Z7="Interdit",0,VLOOKUP(L7,'CODE H VS CODE ICPE'!$A$2:$E$80,5,FALSE))) -> 0 | AP7: =IF(AA7="",0,IF(AA7="Interdit",0,VLOOKUP(M7,'CODE H VS CODE ICPE'!$A$2:$E$80,5,FALSE))) -> 0 | ... AV7: =IF(AG7="",0,IF(AG7="Interdit",0,VLOOKUP(S7,'CODE H VS CODE ICPE'!$A$2:$E$80,5,FALSE))) -> 0 | AW7: =ADDRESS(2,MATCH(MAX(AI7:AV7),AI7:AV7,0)+COLUMN(AI7)-1) -> $AI$2 | AX7: =IF(AH7="Interdit","",IF(AW7="$AI$2",AI7,IF(AW7="$AJ$2",AJ7,IF(AW7="$AK$2",AK7,IF(AW7="$AL$2",AL7,IF(AW7="$AM$2",AM7,IF(AW7="$AN$2",AN7,IF(AW7="$AO$2",AO7,IF(AW7="$AP$2",AP7,IF(AW7="$AQ$2",AQ7,IF(AW7="$AR$2",AR7,IF(AW7="$AS$2",AS7,IF(AW7="$AT$2",AT7,IF(AW7="$AU$2",AU7,IF(AW7="$AV$2",AV7,""))))))))))))))) -> 99999.99 | AY7: =IF(AX7="","",IF(AW7="$AI$2",F7,IF(AW7="$AJ$2",G7,IF(AW7="$AK$2",H7,IF(AW7="$AL$2",I7,IF(AW7="$AM$2",J7,IF(AW7="$AN$2",K7,IF(AW7="$AO$2",L7,IF(AW7="$AP$2",M7,IF(AW7="$AQ$2",N7,IF(AW7="$AR$2",O7,IF(AW7="$AS$2",P7,IF(AW7="$AT$2",Q7,IF(AW7="$AU$2",R7,IF(AW7="$AV$2",S7,""))))))))))))))) -> H225 | AZ7: =IF(AY7="","",IF(AY7=0,"",VLOOKUP(AY7,'CODE H VS CODE ICPE'!$A$1:$E$80,3,FALSE))) -> 4331
A8: 1129 | B8: BUTYRALDÉHYDE | C8: 3 | D8: F1 | E8: BUTYRALDEHYDE | F8: H225 | T8: =IFERROR(VLOOKUP(F8,'CODE H VS CODE ICPE'!$A$2:$D$80,4,FALSE),"") -> Autorisé | U8: =IFERROR(VLOOKUP(G8,'CODE H VS CODE ICPE'!$A$2:$D$80,4,FALSE),"") | V8: =IFERROR(VLOOKUP(H8,'CODE H VS CODE ICPE'!$A$2:$D$80,4,FALSE),"") | W8: =IFERROR(VLOOKUP(I8,'CODE H VS CODE ICPE'!$A$2:$D$80,4,FALSE),"") | X8: =IFERROR(VLOOKUP(J8,'CODE H VS CODE ICPE'!$A$2:$D$80,4,FALSE),"") | Y8: =IFERROR(VLOOKUP(K8,'CODE H VS CODE ICPE'!$A$2:$D$80,4,FALSE),"") | Z8: =IFERROR(VLOOKUP(L8,'CODE H VS CODE ICPE'!$A$2:$D$80,4,FALSE),"") | AA8: =IFERROR(VLOOKUP(M8,'CODE H VS CODE ICPE'!$A$2:$D$80,4,FALSE),"") | ... AG8: =IFERROR(VLOOKUP(S8,'CODE H VS CODE ICPE'!$A$2:$D$80,4,FALSE),"") | AH8: =IF(COUNTIF(T8:AG8, "Rejected") > 0, "Rejected", IF(COUNTIF(T8:AG8, "Under request") > 0, "Under request", "Accepted")) -> Accepted | AI8: =IF(T8="",0,IF(T8="Interdit",0,VLOOKUP(F8,'CODE H VS CODE ICPE'!$A$2:$E$80,5,FALSE))) -> 99999.99 | AJ8: =IF(U8="",0,IF(U8="Interdit",0,VLOOKUP(G8,'CODE H VS CODE ICPE'!$A$2:$E$80,5,FALSE))) -> 0 | AK8: =IF(V8="",0,IF(V8="Interdit",0,VLOOKUP(H8,'CODE H VS CODE ICPE'!$A$2:$E$80,5,FALSE))) -> 0 | AL8: =IF(W8="",0,IF(W8="Interdit",0,VLOOKUP(I8,'CODE H VS CODE ICPE'!$A$2:$E$80,5,FALSE))) -> 0 | AM8: =IF(X8="",0,IF(X8="Interdit",0,VLOOKUP(J8,'CODE H VS CODE ICPE'!$A$2:$E$80,5,FALSE))) -> 0 | AN8: =IF(Y8="",0,IF(Y8="Interdit",0,VLOOKUP(K8,'CODE H VS CODE ICPE'!$A$2:$E$80,5,FALSE))) -> 0 | AO8: =IF(Z8="",0,IF(Z8="Interdit",0,VLOOKUP(L8,'CODE H VS CODE ICPE'!$A$2:$E$80,5,FALSE))) -> 0 | AP8: =IF(AA8="",0,IF(AA8="Interdit",0,VLOOKUP(M8,'CODE H VS CODE ICPE'!$A$2:$E$80,5,FALSE))) -> 0 | ... AV8: =IF(AG8="",0,IF(AG8="Interdit",0,VLOOKUP(S8,'CODE H VS CODE ICPE'!$A$2:$E$80,5,FALSE))) -> 0 | AW8: =ADDRESS(2,MATCH(MAX(AI8:AV8),AI8:AV8,0)+COLUMN(AI8)-1) -> $AI$2 | AX8: =IF(AH8="Interdit","",IF(AW8="$AI$2",AI8,IF(AW8="$AJ$2",AJ8,IF(AW8="$AK$2",AK8,IF(AW8="$AL$2",AL8,IF(AW8="$AM$2",AM8,IF(AW8="$AN$2",AN8,IF(AW8="$AO$2",AO8,IF(AW8="$AP$2",AP8,IF(AW8="$AQ$2",AQ8,IF(AW8="$AR$2",AR8,IF(AW8="$AS$2",AS8,IF(AW8="$AT$2",AT8,IF(AW8="$AU$2",AU8,IF(AW8="$AV$2",AV8,""))))))))))))))) -> 99999.99 | AY8: =IF(AX8="","",IF(AW8="$AI$2",F8,IF(AW8="$AJ$2",G8,IF(AW8="$AK$2",H8,IF(AW8="$AL$2",I8,IF(AW8="$AM$2",J8,IF(AW8="$AN$2",K8,IF(AW8="$AO$2",L8,IF(AW8="$AP$2",M8,IF(AW8="$AQ$2",N8,IF(AW8="$AR$2",O8,IF(AW8="$AS$2",P8,IF(AW8="$AT$2",Q8,IF(AW8="$AU$2",R8,IF(AW8="$AV$2",S8,""))))))))))))))) -> H225 | AZ8: =IF(AY8="","",IF(AY8=0,"",VLOOKUP(AY8,'CODE H VS CODE ICPE'!$A$1:$E$80,3,FALSE))) -> 4331
A9: 1133 | B9: ADHÉSIFS contenant un liquide inflammable | C9: 3 | D9: F1 | E9: ADHESIVES containing flammable liquid | F9: H225 | G9: H302 | I9: H335 | J9: H336 | T9: =IFERROR(VLOOKUP(F9,'CODE H VS CODE ICPE'!$A$2:$D$80,4,FALSE),"") -> Autorisé | U9: =IFERROR(VLOOKUP(G9,'CODE H VS CODE ICPE'!$A$2:$D$80,4,FALSE),"") -> Autorisé | V9: =IFERROR(VLOOKUP(H9,'CODE H VS CODE ICPE'!$A$2:$D$80,4,FALSE),"") | W9: =IFERROR(VLOOKUP(I9,'CODE H VS CODE ICPE'!$A$2:$D$80,4,FALSE),"") -> Autorisé | X9: =IFERROR(VLOOKUP(J9,'CODE H VS CODE ICPE'!$A$2:$D$80,4,FALSE),"") -> Autorisé | Y9: =IFERROR(VLOOKUP(K9,'CODE H VS CODE ICPE'!$A$2:$D$80,4,FALSE),"") | Z9: =IFERROR(VLOOKUP(L9,'CODE H VS CODE ICPE'!$A$2:$D$80,4,FALSE),"") | AA9: =IFERROR(VLOOKUP(M9,'CODE H VS CODE ICPE'!$A$2:$D$80,4,FALSE),"") | ... AG9: =IFERROR(VLOOKUP(S9,'CODE H VS CODE ICPE'!$A$2:$D$80,4,FALSE),"") | AH9: =IF(COUNTIF(T9:AG9, "Rejected") > 0, "Rejected", IF(COUNTIF(T9:AG9, "Under request") > 0, "Under request", "Accepted")) -> Accepted | AI9: =IF(T9="",0,IF(T9="Interdit",0,VLOOKUP(F9,'CODE H VS CODE ICPE'!$A$2:$E$80,5,FALSE))) -> 99999.99 | AJ9: =IF(U9="",0,IF(U9="Interdit",0,VLOOKUP(G9,'CODE H VS CODE ICPE'!$A$2:$E$80,5,FALSE))) -> 99999.99 | AK9: =IF(V9="",0,IF(V9="Interdit",0,VLOOKUP(H9,'CODE H VS CODE ICPE'!$A$2:$E$80,5,FALSE))) -> 0 | AL9: =IF(W9="",0,IF(W9="Interdit",0,VLOOKUP(I9,'CODE H VS CODE ICPE'!$A$2:$E$80,5,FALSE))) -> 99999.99 | AM9: =IF(X9="",0,IF(X9="Interdit",0,VLOOKUP(J9,'CODE H VS CODE ICPE'!$A$2:$E$80,5,FALSE))) -> 99999.99 | AN9: =IF(Y9="",0,IF(Y9="Interdit",0,VLOOKUP(K9,'CODE H VS CODE ICPE'!$A$2:$E$80,5,FALSE))) -> 0 | AO9: =IF(Z9="",0,IF(Z9="Interdit",0,VLOOKUP(L9,'CODE H VS CODE ICPE'!$A$2:$E$80,5,FALSE))) -> 0 | AP9: =IF(AA9="",0,IF(AA9="Interdit",0,VLOOKUP(M9,'CODE H VS CODE ICPE'!$A$2:$E$80,5,FALSE))) -> 0 | ... AV9: =IF(AG9="",0,IF(AG9="Interdit",0,VLOOKUP(S9,'CODE H VS CODE ICPE'!$A$2:$E$80,5,FALSE))) -> 0 | AW9: =ADDRESS(2,MATCH(MAX(AI9:AV9),AI9:AV9,0)+COLUMN(AI9)-1) -> $AI$2 | AX9: =IF(AH9="Interdit","",IF(AW9="$AI$2",AI9,IF(AW9="$AJ$2",AJ9,IF(AW9="$AK$2",AK9,IF(AW9="$AL$2",AL9,IF(AW9="$AM$2",AM9,IF(AW9="$AN$2",AN9,IF(AW9="$AO$2",AO9,IF(AW9="$AP$2",AP9,IF(AW9="$AQ$2",AQ9,IF(AW9="$AR$2",AR9,IF(AW9="$AS$2",AS9,IF(AW9="$AT$2",AT9,IF(AW9="$AU$2",AU9,IF(AW9="$AV$2",AV9,""))))))))))))))) -> 99999.99 | AY9: =IF(AX9="","",IF(AW9="$AI$2",F9,IF(AW9="$AJ$2",G9,IF(AW9="$AK$2",H9,IF(AW9="$AL$2",I9,IF(AW9="$AM$2",J9,IF(AW9="$AN$2",K9,IF(AW9="$AO$2",L9,IF(AW9="$AP$2",M9,IF(AW9="$AQ$2",N9,IF(AW9="$AR$2",O9,IF(AW9="$AS$2",P9,IF(AW9="$AT$2",Q9,IF(AW9="$AU$2",R9,IF(AW9="$AV$2",S9,""))))))))))))))) -> H225 | AZ9: =IF(AY9="","",IF(AY9=0,"",VLOOKUP(AY9,'CODE H VS CODE ICPE'!$A$1:$E$80,3,FALSE))) -> 4331
A10: 1139 | B10: SOLUTION D'ENROBAGE (traitements de surface ou enrobages utilisés dans l'industrie ou à d'autres fins, tels que sous-couche pour carrosserie de véhicule, revêtement pour fûts et tonneaux) | C10: 3 | D10: F1 | E10: COATING SOLUTION (includes surface treatments or coatings used for industrial or other purposes such as vehicle under coating, drum or barrel lining) | F10: H225 | G10: H226 | T10: =IFERROR(VLOOKUP(F10,'CODE H VS CODE ICPE'!$A$2:$D$80,4,FALSE),"") -> Autorisé | U10: =IFERROR(VLOOKUP(G10,'CODE H VS CODE ICPE'!$A$2:$D$80,4,FALSE),"") -> Autorisé | V10: =IFERROR(VLOOKUP(H10,'CODE H VS CODE ICPE'!$A$2:$D$80,4,FALSE),"") | W10: =IFERROR(VLOOKUP(I10,'CODE H VS CODE ICPE'!$A$2:$D$80,4,FALSE),"") | X10: =IFERROR(VLOOKUP(J10,'CODE H VS CODE ICPE'!$A$2:$D$80,4,FALSE),"") | Y10: =IFERROR(VLOOKUP(K10,'CODE H VS CODE ICPE'!$A$2:$D$80,4,FALSE),"") | Z10: =IFERROR(VLOOKUP(L10,'CODE H VS CODE ICPE'!$A$2:$D$80,4,FALSE),"") | AA10: =IFERROR(VLOOKUP(M10,'CODE H VS CODE ICPE'!$A$2:$D$80,4,FALSE),"") | ... AG10: =IFERROR(VLOOKUP(S10,'CODE H VS CODE ICPE'!$A$2:$D$80,4,FALSE),"") | AH10: =IF(COUNTIF(T10:AG10, "Rejected") > 0, "Rejected", IF(COUNTIF(T10:AG10, "Under request") > 0, "Under request", "Accepted")) -> Accepted | AI10: =IF(T10="",0,IF(T10="Interdit",0,VLOOKUP(F10,'CODE H VS CODE ICPE'!$A$2:$E$80,5,FALSE))) -> 99999.99 | AJ10: =IF(U10="",0,IF(U10="Interdit",0,VLOOKUP(G10,'CODE H VS CODE ICPE'!$A$2:$E$80,5,FALSE))) -> 99999.99 | AK10: =IF(V10="",0,IF(V10="Interdit",0,VLOOKUP(H10,'CODE H VS CODE ICPE'!$A$2:$E$80,5,FALSE))) -> 0 | AL10: =IF(W10="",0,IF(W10="Interdit",0,VLOOKUP(I10,'CODE H VS CODE ICPE'!$A$2:$E$80,5,FALSE))) -> 0 | AM10: =IF(X10="",0,IF(X10="Interdit",0,VLOOKUP(J10,'CODE H VS CODE ICPE'!$A$2:$E$80,5,FALSE))) -> 0 | AN10: =IF(Y10="",0,IF(Y10="Interdit",0,VLOOKUP(K10,'CODE H VS CODE ICPE'!$A$2:$E$80,5,FALSE))) -> 0 | AO10: =IF(Z10="",0,IF(Z10="Interdit",0,VLOOKUP(L10,'CODE H VS CODE ICPE'!$A$2:$E$80,5,FALSE))) -> 0 | AP10: =IF(AA10="",0,IF(AA10="Interdit",0,VLOOKUP(M10,'CODE H VS CODE ICPE'!$A$2:$E$80,5,FALSE))) -> 0 | ... AV10: =IF(AG10="",0,IF(AG10="Interdit",0,VLOOKUP(S10,'CODE H VS CODE ICPE'!$A$2:$E$80,5,FALSE))) -> 0 | AW10: =ADDRESS(2,MATCH(MAX(AI10:AV10),AI10:AV10,0)+COLUMN(AI10)-1) -> $AI$2 | AX10: =IF(AH10="Interdit","",IF(AW10="$AI$2",AI10,IF(AW10="$AJ$2",AJ10,IF(AW10="$AK$2",AK10,IF(AW10="$AL$2",AL10,IF(AW10="$AM$2",AM10,IF(AW10="$AN$2",AN10,IF(AW10="$AO$2",AO10,IF(AW10="$AP$2",AP10,IF(AW10="$AQ$2",AQ10,IF(AW10="$AR$2",AR10,IF(AW10="$AS$2",AS10,IF(AW10="$AT$2",AT10,IF(AW10="$AU$2",AU10,IF(AW10="$AV$2",AV10,""))))))))))))))) -> 99999.99 | AY10: =IF(AX10="","",IF(AW10="$AI$2",F10,IF(AW10="$AJ$2",G10,IF(AW10="$AK$2",H10,IF(AW10="$AL$2",I10,IF(AW10="$AM$2",J10,IF(AW10="$AN$2",K10,IF(AW10="$AO$2",L10,IF(AW10="$AP$2",M10,IF(AW10="$AQ$2",N10,IF(AW10="$AR$2",O10,IF(AW10="$AS$2",P10,IF(AW10="$AT$2",Q10,IF(AW10="$AU$2",R10,IF(AW10="$AV$2",S10,""))))))))))))))) -> H225 | AZ10: =IF(AY10="","",IF(AY10=0,"",VLOOKUP(AY10,'CODE H VS CODE ICPE'!$A$1:$E$80,3,FALSE))) -> 4331
A11: 1146 | B11: CYCLOPENTANE | C11: 3 | D11: F1 | E11: CYCLOPENTANE | F11: H225 | G11: H412 | T11: =IFERROR(VLOOKUP(F11,'CODE H VS CODE ICPE'!$A$2:$D$80,4,FALSE),"") -> Autorisé | U11: =IFERROR(VLOOKUP(G11,'CODE H VS CODE ICPE'!$A$2:$D$80,4,FALSE),"") -> Autorisé | V11: =IFERROR(VLOOKUP(H11,'CODE H VS CODE ICPE'!$A$2:$D$80,4,FALSE),"") | W11: =IFERROR(VLOOKUP(I11,'CODE H VS CODE ICPE'!$A$2:$D$80,4,FALSE),"") | X11: =IFERROR(VLOOKUP(J11,'CODE H VS CODE ICPE'!$A$2:$D$80,4,FALSE),"") | Y11: =IFERROR(VLOOKUP(K11,'CODE H VS CODE ICPE'!$A$2:$D$80,4,FALSE),"") | Z11: =IFERROR(VLOOKUP(L11,'CODE H VS CODE ICPE'!$A$2:$D$80,4,FALSE),"") | AA11: =IFERROR(VLOOKUP(M11,'CODE H VS CODE ICPE'!$A$2:$D$80,4,FALSE),"") | ... AG11: =IFERROR(VLOOKUP(S11,'CODE H VS CODE ICPE'!$A$2:$D$80,4,FALSE),"") | AH11: =IF(COUNTIF(T11:AG11, "Rejected") > 0, "Rejected", IF(COUNTIF(T11:AG11, "Under request") > 0, "Under request", "Accepted")) -> Accepted | AI11: =IF(T11="",0,IF(T11="Interdit",0,VLOOKUP(F11,'CODE H VS CODE ICPE'!$A$2:$E$80,5,FALSE))) -> 99999.99 | AJ11: =IF(U11="",0,IF(U11="Interdit",0,VLOOKUP(G11,'CODE H VS CODE ICPE'!$A$2:$E$80,5,FALSE))) -> 99999.99 | AK11: =IF(V11="",0,IF(V11="Interdit",0,VLOOKUP(H11,'CODE H VS CODE ICPE'!$A$2:$E$80,5,FALSE))) -> 0 | AL11: =IF(W11="",0,IF(W11="Interdit",0,VLOOKUP(I11,'CODE H VS CODE ICPE'!$A$2:$E$80,5,FALSE))) -> 0 | AM11: =IF(X11="",0,IF(X11="Interdit",0,VLOOKUP(J11,'CODE H VS CODE ICPE'!$A$2:$E$80,5,FALSE))) -> 0 | AN11: =IF(Y11="",0,IF(Y11="Interdit",0,VLOOKUP(K11,'CODE H VS CODE ICPE'!$A$2:$E$80,5,FALSE))) -> 0 | AO11: =IF(Z11="",0,IF(Z11="Interdit",0,VLOOKUP(L11,'CODE H VS CODE ICPE'!$A$2:$E$80,5,FALSE))) -> 0 | AP11: =IF(AA11="",0,IF(AA11="Interdit",0,VLOOKUP(M11,'CODE H VS CODE ICPE'!$A$2:$E$80,5,FALSE))) -> 0 | ... AV11: =IF(AG11="",0,IF(AG11="Interdit",0,VLOOKUP(S11,'CODE H VS CODE ICPE'!$A$2:$E$80,5,FALSE))) -> 0 | AW11: =ADDRESS(2,MATCH(MAX(AI11:AV11),AI11:AV11,0)+COLUMN(AI11)-1) -> $AI$2 | AX11: =IF(AH11="Interdit","",IF(AW11="$AI$2",AI11,IF(AW11="$AJ$2",AJ11,IF(AW11="$AK$2",AK11,IF(AW11="$AL$2",AL11,IF(AW11="$AM$2",AM11,IF(AW11="$AN$2",AN11,IF(AW11="$AO$2",AO11,IF(AW11="$AP$2",AP11,IF(AW11="$AQ$2",AQ11,IF(AW11="$AR$2",AR11,IF(AW11="$AS$2",AS11,IF(AW11="$AT$2",AT11,IF(AW11="$AU$2",AU11,IF(AW11="$AV$2",AV11,""))))))))))))))) -> 99999.99 | AY11: =IF(AX11="","",IF(AW11="$AI$2",F11,IF(AW11="$AJ$2",G11,IF(AW11="$AK$2",H11,IF(AW11="$AL$2",I11,IF(AW11="$AM$2",J11,IF(AW11="$AN$2",K11,IF(AW11="$AO$2",L11,IF(AW11="$AP$2",M11,IF(AW11="$AQ$2",N11,IF(AW11="$AR$2",O11,IF(AW11="$AS$2",P11,IF(AW11="$AT$2",Q11,IF(AW11="$AU$2",R11,IF(AW11="$AV$2",S11,""))))))))))))))) -> H225 | AZ11: =IF(AY11="","",IF(AY11=0,"",VLOOKUP(AY11,'CODE H VS CODE ICPE'!$A$1:$E$80,3,FALSE))) -> 4331
A12: 1149 | B12: ÉTHERS BUTYLIQUES | C12: 3 | D12: F1 | E12: DIBUTYL ETHERS | F12: H225 | G12: H336 | T12: =IFERROR(VLOOKUP(F12,'CODE H VS CODE ICPE'!$A$2:$D$80,4,FALSE),"") -> Autorisé | U12: =IFERROR(VLOOKUP(G12,'CODE H VS CODE ICPE'!$A$2:$D$80,4,FALSE),"") -> Autorisé | V12: =IFERROR(VLOOKUP(H12,'CODE H VS CODE ICPE'!$A$2:$D$80,4,FALSE),"") | W12: =IFERROR(VLOOKUP(I12,'CODE H VS CODE ICPE'!$A$2:$D$80,4,FALSE),"") | X12: =IFERROR(VLOOKUP(J12,'CODE H VS CODE ICPE'!$A$2:$D$80,4,FALSE),"") | Y12: =IFERROR(VLOOKUP(K12,'CODE H VS CODE ICPE'!$A$2:$D$80,4,FALSE),"") | Z12: =IFERROR(VLOOKUP(L12,'CODE H VS CODE ICPE'!$A$2:$D$80,4,FALSE),"") | AA12: =IFERROR(VLOOKUP(M12,'CODE H VS CODE ICPE'!$A$2:$D$80,4,FALSE),"") | ... AG12: =IFERROR(VLOOKUP(S12,'CODE H VS CODE ICPE'!$A$2:$D$80,4,FALSE),"") | AH12: =IF(COUNTIF(T12:AG12, "Rejected") > 0, "Rejected", IF(COUNTIF(T12:AG12, "Under request") > 0, "Under request", "Accepted")) -> Accepted | AI12: =IF(T12="",0,IF(T12="Interdit",0,VLOOKUP(F12,'CODE H VS CODE ICPE'!$A$2:$E$80,5,FALSE))) -> 99999.99 | AJ12: =IF(U12="",0,IF(U12="Interdit",0,VLOOKUP(G12,'CODE H VS CODE ICPE'!$A$2:$E$80,5,FALSE))) -> 99999.99 | AK12: =IF(V12="",0,IF(V12="Interdit",0,VLOOKUP(H12,'CODE H VS CODE ICPE'!$A$2:$E$80,5,FALSE))) -> 0 | AL12: =IF(W12="",0,IF(W12="Interdit",0,VLOOKUP(I12,'CODE H VS CODE ICPE'!$A$2:$E$80,5,FALSE))) -> 0 | AM12: =IF(X12="",0,IF(X12="Interdit",0,VLOOKUP(J12,'CODE H VS CODE ICPE'!$A$2:$E$80,5,FALSE))) -> 0 | AN12: =IF(Y12="",0,IF(Y12="Interdit",0,VLOOKUP(K12,'CODE H VS CODE ICPE'!$A$2:$E$80,5,FALSE))) -> 0 | AO12: =IF(Z12="",0,IF(Z12="Interdit",0,VLOOKUP(L12,'CODE H VS CODE ICPE'!$A$2:$E$80,5,FALSE))) -> 0 | AP12: =IF(AA12="",0,IF(AA12="Interdit",0,VLOOKUP(M12,'CODE H VS CODE ICPE'!$A$2:$E$80,5,FALSE))) -> 0 | ... AV12: =IF(AG12="",0,IF(AG12="Interdit",0,VLOOKUP(S12,'CODE H VS CODE ICPE'!$A$2:$E$80,5,FALSE))) -> 0 | AW12: =ADDRESS(2,MATCH(MAX(AI12:AV12),AI12:AV12,0)+COLUMN(AI12)-1) -> $AI$2 | AX12: =IF(AH12="Interdit","",IF(AW12="$AI$2",AI12,IF(AW12="$AJ$2",AJ12,IF(AW12="$AK$2",AK12,IF(AW12="$AL$2",AL12,IF(AW12="$AM$2",AM12,IF(AW12="$AN$2",AN12,IF(AW12="$AO$2",AO12,IF(AW12="$AP$2",AP12,IF(AW12="$AQ$2",AQ12,IF(AW12="$AR$2",AR12,IF(AW12="$AS$2",AS12,IF(AW12="$AT$2",AT12,IF(AW12="$AU$2",AU12,IF(AW12="$AV$2",AV12,""))))))))))))))) -> 99999.99 | AY12: =IF(AX12="","",IF(AW12="$AI$2",F12,IF(AW12="$AJ$2",G12,IF(AW12="$AK$2",H12,IF(AW12="$AL$2",I12,IF(AW12="$AM$2",J12,IF(AW12="$AN$2",K12,IF(AW12="$AO$2",L12,IF(AW12="$AP$2",M12,IF(AW12="$AQ$2",N12,IF(AW12="$AR$2",O12,IF(AW12="$AS$2",P12,IF(AW12="$AT$2",Q12,IF(AW12="$AU$2",R12,IF(AW12="$AV$2",S12,""))))))))))))))) -> H225 | AZ12: =IF(AY12="","",IF(AY12=0,"",VLOOKUP(AY12,'CODE H VS CODE ICPE'!$A$1:$E$80,3,FALSE))) -> 4331
A13: 1156 | B13: DIÉTHYLCÉTONE | C13: 3 | D13: F1 | E13: DIETHYL KETONE | F13: H225 | G13: H319 | H13: H335 | I13: H336 | T13: =IFERROR(VLOOKUP(F13,'CODE H VS CODE ICPE'!$A$2:$D$80,4,FALSE),"") -> Autorisé | U13: =IFERROR(VLOOKUP(G13,'CODE H VS CODE ICPE'!$A$2:$D$80,4,FALSE),"") -> Autorisé | V13: =IFERROR(VLOOKUP(H13,'CODE H VS CODE ICPE'!$A$2:$D$80,4,FALSE),"") -> Autorisé | W13: =IFERROR(VLOOKUP(I13,'CODE H VS CODE ICPE'!$A$2:$D$80,4,FALSE),"") -> Autorisé | X13: =IFERROR(VLOOKUP(J13,'CODE H VS CODE ICPE'!$A$2:$D$80,4,FALSE),"") | Y13: =IFERROR(VLOOKUP(K13,'CODE H VS CODE ICPE'!$A$2:$D$80,4,FALSE),"") | Z13: =IFERROR(VLOOKUP(L13,'CODE H VS CODE ICPE'!$A$2:$D$80,4,FALSE),"") | AA13: =IFERROR(VLOOKUP(M13,'CODE H VS CODE ICPE'!$A$2:$D$80,4,FALSE),"") | ... AG13: =IFERROR(VLOOKUP(S13,'CODE H VS CODE ICPE'!$A$2:$D$80,4,FALSE),"") | AH13: =IF(COUNTIF(T13:AG13, "Rejected") > 0, "Rejected", IF(COUNTIF(T13:AG13, "Under request") > 0, "Under request", "Accepted")) -> Accepted | AI13: =IF(T13="",0,IF(T13="Interdit",0,VLOOKUP(F13,'CODE H VS CODE ICPE'!$A$2:$E$80,5,FALSE))) -> 99999.99 | AJ13: =IF(U13="",0,IF(U13="Interdit",0,VLOOKUP(G13,'CODE H VS CODE ICPE'!$A$2:$E$80,5,FALSE))) -> 99999.99 | AK13: =IF(V13="",0,IF(V13="Interdit",0,VLOOKUP(H13,'CODE H VS CODE ICPE'!$A$2:$E$80,5,FALSE))) -> 99999.99 | AL13: =IF(W13="",0,IF(W13="Interdit",0,VLOOKUP(I13,'CODE H VS CODE ICPE'!$A$2:$E$80,5,FALSE))) -> 99999.99 | AM13: =IF(X13="",0,IF(X13="Interdit",0,VLOOKUP(J13,'CODE H VS CODE ICPE'!$A$2:$E$80,5,FALSE))) -> 0 | AN13: =IF(Y13="",0,IF(Y13="Interdit",0,VLOOKUP(K13,'CODE H VS CODE ICPE'!$A$2:$E$80,5,FALSE))) -> 0 | AO13: =IF(Z13="",0,IF(Z13="Interdit",0,VLOOKUP(L13,'CODE H VS CODE ICPE'!$A$2:$E$80,5,FALSE))) -> 0 | AP13: =IF(AA13="",0,IF(AA13="Interdit",0,VLOOKUP(M13,'CODE H VS CODE ICPE'!$A$2:$E$80,5,FALSE))) -> 0 | ... AV13: =IF(AG13="",0,IF(AG13="Interdit",0,VLOOKUP(S13,'CODE H VS CODE ICPE'!$A$2:$E$80,5,FALSE))) -> 0 | AW13: =ADDRESS(2,MATCH(MAX(AI13:AV13),AI13:AV13,0)+COLUMN(AI13)-1) -> $AI$2 | AX13: =IF(AH13="Interdit","",IF(AW13="$AI$2",AI13,IF(AW13="$AJ$2",AJ13,IF(AW13="$AK$2",AK13,IF(AW13="$AL$2",AL13,IF(AW13="$AM$2",AM13,IF(AW13="$AN$2",AN13,IF(AW13="$AO$2",AO13,IF(AW13="$AP$2",AP13,IF(AW13="$AQ$2",AQ13,IF(AW13="$AR$2",AR13,IF(AW13="$AS$2",AS13,IF(AW13="$AT$2",AT13,IF(AW13="$AU$2",AU13,IF(AW13="$AV$2",AV13,""))))))))))))))) -> 99999.99 | AY13: =IF(AX13="","",IF(AW13="$AI$2",F13,IF(AW13="$AJ$2",G13,IF(AW13="$AK$2",H13,IF(AW13="$AL$2",I13,IF(AW13="$AM$2",J13,IF(AW13="$AN$2",K13,IF(AW13="$AO$2",L13,IF(AW13="$AP$2",M13,IF(AW13="$AQ$2",N13,IF(AW13="$AR$2",O13,IF(AW13="$AS$2",P13,IF(AW13="$AT$2",Q13,IF(AW13="$AU$2",R13,IF(AW13="$AV$2",S13,""))))))))))))))) -> H225 | AZ13: =IF(AY13="","",IF(AY13=0,"",VLOOKUP(AY13,'CODE H VS CODE ICPE'!$A$1:$E$80,3,FALSE))) -> 4331
A14: 1157 | B14: DIISOBUTYLCÉTONE | C14: 3 | D14: F1 | E14: DIISOBUTYL KETONE | F14: H226 | G14: H335 | T14: =IFERROR(VLOOKUP(F14,'CODE H VS CODE ICPE'!$A$2:$D$80,4,FALSE),"") -> Autorisé | U14: =IFERROR(VLOOKUP(G14,'CODE H VS CODE ICPE'!$A$2:$D$80,4,FALSE),"") -> Autorisé | V14: =IFERROR(VLOOKUP(H14,'CODE H VS CODE ICPE'!$A$2:$D$80,4,FALSE),"") | W14: =IFERROR(VLOOKUP(I14,'CODE H VS CODE ICPE'!$A$2:$D$80,4,FALSE),"") | X14: =IFERROR(VLOOKUP(J14,'CODE H VS CODE ICPE'!$A$2:$D$80,4,FALSE),"") | Y14: =IFERROR(VLOOKUP(K14,'CODE H VS CODE ICPE'!$A$2:$D$80,4,FALSE),"") | Z14: =IFERROR(VLOOKUP(L14,'CODE H VS CODE ICPE'!$A$2:$D$80,4,FALSE),"") | AA14: =IFERROR(VLOOKUP(M14,'CODE H VS CODE ICPE'!$A$2:$D$80,4,FALSE),"") | ... AG14: =IFERROR(VLOOKUP(S14,'CODE H VS CODE ICPE'!$A$2:$D$80,4,FALSE),"") | AH14: =IF(COUNTIF(T14:AG14, "Rejected") > 0, "Rejected", IF(COUNTIF(T14:AG14, "Under request") > 0, "Under request", "Accepted")) -> Accepted | AI14: =IF(T14="",0,IF(T14="Interdit",0,VLOOKUP(F14,'CODE H VS CODE ICPE'!$A$2:$E$80,5,FALSE))) -> 99999.99 | AJ14: =IF(U14="",0,IF(U14="Interdit",0,VLOOKUP(G14,'CODE H VS CODE ICPE'!$A$2:$E$80,5,FALSE))) -> 99999.99 | AK14: =IF(V14="",0,IF(V14="Interdit",0,VLOOKUP(H14,'CODE H VS CODE ICPE'!$A$2:$E$80,5,FALSE))) -> 0 | AL14: =IF(W14="",0,IF(W14="Interdit",0,VLOOKUP(I14,'CODE H VS CODE ICPE'!$A$2:$E$80,5,FALSE))) -> 0 | AM14: =IF(X14="",0,IF(X14="Interdit",0,VLOOKUP(J14,'CODE H VS CODE ICPE'!$A$2:$E$80,5,FALSE))) -> 0 | AN14: =IF(Y14="",0,IF(Y14="Interdit",0,VLOOKUP(K14,'CODE H VS CODE ICPE'!$A$2:$E$80,5,FALSE))) -> 0 | AO14: =IF(Z14="",0,IF(Z14="Interdit",0,VLOOKUP(L14,'CODE H VS CODE ICPE'!$A$2:$E$80,5,FALSE))) -> 0 | AP14: =IF(AA14="",0,IF(AA14="Interdit",0,VLOOKUP(M14,'CODE H VS CODE ICPE'!$A$2:$E$80,5,FALSE))) -> 0 | ... AV14: =IF(AG14="",0,IF(AG14="Interdit",0,VLOOKUP(S14,'CODE H VS CODE ICPE'!$A$2:$E$80,5,FALSE))) -> 0 | AW14: =ADDRESS(2,MATCH(MAX(AI14:AV14),AI14:AV14,0)+COLUMN(AI14)-1) -> $AI$2 | AX14: =IF(AH14="Interdit","",IF(AW14="$AI$2",AI14,IF(AW14="$AJ$2",AJ14,IF(AW14="$AK$2",AK14,IF(AW14="$AL$2",AL14,IF(AW14="$AM$2",AM14,IF(AW14="$AN$2",AN14,IF(AW14="$AO$2",AO14,IF(AW14="$AP$2",AP14,IF(AW14="$AQ$2",AQ14,IF(AW14="$AR$2",AR14,IF(AW14="$AS$2",AS14,IF(AW14="$AT$2",AT14,IF(AW14="$AU$2",AU14,IF(AW14="$AV$2",AV14,""))))))))))))))) -> 99999.99 | AY14: =IF(AX14="","",IF(AW14="$AI$2",F14,IF(AW14="$AJ$2",G14,IF(AW14="$AK$2",H14,IF(AW14="$AL$2",I14,IF(AW14="$AM$2",J14,IF(AW14="$AN$2",K14,IF(AW14="$AO$2",L14,IF(AW14="$AP$2",M14,IF(AW14="$AQ$2",N14,IF(AW14="$AR$2",O14,IF(AW14="$AS$2",P14,IF(AW14="$AT$2",Q14,IF(AW14="$AU$2",R14,IF(AW14="$AV$2",S14,""))))))))))))))) -> H226 | AZ14: =IF(AY14="","",IF(AY14=0,"",VLOOKUP(AY14,'CODE H VS CODE ICPE'!$A$1:$E$80,3,FALSE))) -> 4331
A15: 1158 | B15: DIISOPROPYLAMINE | C15: 3 | D15: FC | E15: DIISOPROPYLAMINE | F15: H225 | G15: H302 | H15: H314 | I15: H331 | J15: H335 | K15: H412 | T15: =IFERROR(VLOOKUP(F15,'CODE H VS CODE ICPE'!$A$2:$D$80,4,FALSE),"") -> Autorisé | U15: =IFERROR(VLOOKUP(G15,'CODE H VS CODE ICPE'!$A$2:$D$80,4,FALSE),"") -> Autorisé | V15: =IFERROR(VLOOKUP(H15,'CODE H VS CODE ICPE'!$A$2:$D$80,4,FALSE),"") -> Autorisé | W15: =IFERROR(VLOOKUP(I15,'CODE H VS CODE ICPE'!$A$2:$D$80,4,FALSE),"") -> Autorisé | X15: =IFERROR(VLOOKUP(J15,'CODE H VS CODE ICPE'!$A$2:$D$80,4,FALSE),"") -> Autorisé | Y15: =IFERROR(VLOOKUP(K15,'CODE H VS CODE ICPE'!$A$2:$D$80,4,FALSE),"") -> Autorisé | Z15: =IFERROR(VLOOKUP(L15,'CODE H VS CODE ICPE'!$A$2:$D$80,4,FALSE),"") | AA15: =IFERROR(VLOOKUP(M15,'CODE H VS CODE ICPE'!$A$2:$D$80,4,FALSE),"") | ... AG15: =IFERROR(VLOOKUP(S15,'CODE H VS CODE ICPE'!$A$2:$D$80,4,FALSE),"") | AH15: =IF(COUNTIF(T15:AG15, "Rejected") > 0, "Rejected", IF(COUNTIF(T15:AG15, "Under request") > 0, "Under request", "Accepted")) -> Accepted | AI15: =IF(T15="",0,IF(T15="Interdit",0,VLOOKUP(F15,'CODE H VS CODE ICPE'!$A$2:$E$80,5,FALSE))) -> 99999.99 | AJ15: =IF(U15="",0,IF(U15="Interdit",0,VLOOKUP(G15,'CODE H VS CODE ICPE'!$A$2:$E$80,5,FALSE))) -> 99999.99 | AK15: =IF(V15="",0,IF(V15="Interdit",0,VLOOKUP(H15,'CODE H VS CODE ICPE'!$A$2:$E$80,5,FALSE))) -> 149999.99 | AL15: =IF(W15="",0,IF(W15="Interdit",0,VLOOKUP(I15,'CODE H VS CODE ICPE'!$A$2:$E$80,5,FALSE))) -> 99999.99 | AM15: =IF(X15="",0,IF(X15="Interdit",0,VLOOKUP(J15,'CODE H VS CODE ICPE'!$A$2:$E$80,5,FALSE))) -> 99999.99 | AN15: =IF(Y15="",0,IF(Y15="Interdit",0,VLOOKUP(K15,'CODE H VS CODE ICPE'!$A$2:$E$80,5,FALSE))) -> 99999.99 | AO15: =IF(Z15="",0,IF(Z15="Interdit",0,VLOOKUP(L15,'CODE H VS CODE ICPE'!$A$2:$E$80,5,FALSE))) -> 0 | AP15: =IF(AA15="",0,IF(AA15="Interdit",0,VLOOKUP(M15,'CODE H VS CODE ICPE'!$A$2:$E$80,5,FALSE))) -> 0 | ... AV15: =IF(AG15="",0,IF(AG15="Interdit",0,VLOOKUP(S15,'CODE H VS CODE ICPE'!$A$2:$E$80,5,FALSE))) -> 0 | AW15: =ADDRESS(2,MATCH(MAX(AI15:AV15),AI15:AV15,0)+COLUMN(AI15)-1) -> $AK$2 | AX15: =IF(AH15="Interdit","",IF(AW15="$AI$2",AI15,IF(AW15="$AJ$2",AJ15,IF(AW15="$AK$2",AK15,IF(AW15="$AL$2",AL15,IF(AW15="$AM$2",AM15,IF(AW15="$AN$2",AN15,IF(AW15="$AO$2",AO15,IF(AW15="$AP$2",AP15,IF(AW15="$AQ$2",AQ15,IF(AW15="$AR$2",AR15,IF(AW15="$AS$2",AS15,IF(AW15="$AT$2",AT15,IF(AW15="$AU$2",AU15,IF(AW15="$AV$2",AV15,""))))))))))))))) -> 149999.99 | AY15: =IF(AX15="","",IF(AW15="$AI$2",F15,IF(AW15="$AJ$2",G15,IF(AW15="$AK$2",H15,IF(AW15="$AL$2",I15,IF(AW15="$AM$2",J15,IF(AW15="$AN$2",K15,IF(AW15="$AO$2",L15,IF(AW15="$AP$2",M15,IF(AW15="$AQ$2",N15,IF(AW15="$AR$2",O15,IF(AW15="$AS$2",P15,IF(AW15="$AT$2",Q15,IF(AW15="$AU$2",R15,IF(AW15="$AV$2",S15,""))))))))))))))) -> H314 | AZ15: =IF(AY15="","",IF(AY15=0,"",VLOOKUP(AY15,'CODE H VS CODE ICPE'!$A$1:$E$80,3,FALSE))) -> 4320
A16: 1159 | B16: ÉTHER ISOPROPYLIQUE | C16: 3 | D16: F1 | E16: DIISOPROPYL ETHER | F16: H225 | G16: H336 | T16: =IFERROR(VLOOKUP(F16,'CODE H VS CODE ICPE'!$A$2:$D$80,4,FALSE),"") -> Autorisé | U16: =IFERROR(VLOOKUP(G16,'CODE H VS CODE ICPE'!$A$2:$D$80,4,FALSE),"") -> Autorisé | V16: =IFERROR(VLOOKUP(H16,'CODE H VS CODE ICPE'!$A$2:$D$80,4,FALSE),"") | W16: =IFERROR(VLOOKUP(I16,'CODE H VS CODE ICPE'!$A$2:$D$80,4,FALSE),"") | X16: =IFERROR(VLOOKUP(J16,'CODE H VS CODE ICPE'!$A$2:$D$80,4,FALSE),"") | Y16: =IFERROR(VLOOKUP(K16,'CODE H VS CODE ICPE'!$A$2:$D$80,4,FALSE),"") | Z16: =IFERROR(VLOOKUP(L16,'CODE H VS CODE ICPE'!$A$2:$D$80,4,FALSE),"") | AA16: =IFERROR(VLOOKUP(M16,'CODE H VS CODE ICPE'!$A$2:$D$80,4,FALSE),"") | ... AG16: =IFERROR(VLOOKUP(S16,'CODE H VS CODE ICPE'!$A$2:$D$80,4,FALSE),"") | AH16: =IF(COUNTIF(T16:AG16, "Rejected") > 0, "Rejected", IF(COUNTIF(T16:AG16, "Under request") > 0, "Under request", "Accepted")) -> Accepted | AI16: =IF(T16="",0,IF(T16="Interdit",0,VLOOKUP(F16,'CODE H VS CODE ICPE'!$A$2:$E$80,5,FALSE))) -> 99999.99 | AJ16: =IF(U16="",0,IF(U16="Interdit",0,VLOOKUP(G16,'CODE H VS CODE ICPE'!$A$2:$E$80,5,FALSE))) -> 99999.99 | AK16: =IF(V16="",0,IF(V16="Interdit",0,VLOOKUP(H16,'CODE H VS CODE ICPE'!$A$2:$E$80,5,FALSE))) -> 0 | AL16: =IF(W16="",0,IF(W16="Interdit",0,VLOOKUP(I16,'CODE H VS CODE ICPE'!$A$2:$E$80,5,FALSE))) -> 0 | AM16: =IF(X16="",0,IF(X16="Interdit",0,VLOOKUP(J16,'CODE H VS CODE ICPE'!$A$2:$E$80,5,FALSE))) -> 0 | AN16: =IF(Y16="",0,IF(Y16="Interdit",0,VLOOKUP(K16,'CODE H VS CODE ICPE'!$A$2:$E$80,5,FALSE))) -> 0 | AO16: =IF(Z16="",0,IF(Z16="Interdit",0,VLOOKUP(L16,'CODE H VS CODE ICPE'!$A$2:$E$80,5,FALSE))) -> 0 | AP16: =IF(AA16="",0,IF(AA16="Interdit",0,VLOOKUP(M16,'CODE H VS CODE ICPE'!$A$2:$E$80,5,FALSE))) -> 0 | ... AV16: =IF(AG16="",0,IF(AG16="Interdit",0,VLOOKUP(S16,'CODE H VS CODE ICPE'!$A$2:$E$80,5,FALSE))) -> 0 | AW16: =ADDRESS(2,MATCH(MAX(AI16:AV16),AI16:AV16,0)+COLUMN(AI16)-1) -> $AI$2 | AX16: =IF(AH16="Interdit","",IF(AW16="$AI$2",AI16,IF(AW16="$AJ$2",AJ16,IF(AW16="$AK$2",AK16,IF(AW16="$AL$2",AL16,IF(AW16="$AM$2",AM16,IF(AW16="$AN$2",AN16,IF(AW16="$AO$2",AO16,IF(AW16="$AP$2",AP16,IF(AW16="$AQ$2",AQ16,IF(AW16="$AR$2",AR16,IF(AW16="$AS$2",AS16,IF(AW16="$AT$2",AT16,IF(AW16="$AU$2",AU16,IF(AW16="$AV$2",AV16,""))))))))))))))) -> 99999.99 | AY16: =IF(AX16="","",IF(AW16="$AI$2",F16,IF(AW16="$AJ$2",G16,IF(AW16="$AK$2",H16,IF(AW16="$AL$2",I16,IF(AW16="$AM$2",J16,IF(AW16="$AN$2",K16,IF(AW16="$AO$2",L16,IF(AW16="$AP$2",M16,IF(AW16="$AQ$2",N16,IF(AW16="$AR$2",O16,IF(AW16="$AS$2",P16,IF(AW16="$AT$2",Q16,IF(AW16="$AU$2",R16,IF(AW16="$AV$2",S16,""))))))))))))))) -> H225 | AZ16: =IF(AY16="","",IF(AY16=0,"",VLOOKUP(AY16,'CODE H VS CODE ICPE'!$A$1:$E$80,3,FALSE))) -> 4331
A17: 1160 | B17: DIMÉTHYLAMINE EN SOLUTION AQUEUSE | C17: 3 | D17: FC | E17: DIMETHYLAMINE AQUEOUS SOLUTION | F17: H225 | G17: H302 | H17: H314 | I17: H335 | J17: H412 | T17: =IFERROR(VLOOKUP(F17,'CODE H VS CODE ICPE'!$A$2:$D$80,4,FALSE),"") -> Autorisé | U17: =IFERROR(VLOOKUP(G17,'CODE H VS CODE ICPE'!$A$2:$D$80,4,FALSE),"") -> Autorisé | V17: =IFERROR(VLOOKUP(H17,'CODE H VS CODE ICPE'!$A$2:$D$80,4,FALSE),"") -> Autorisé | W17: =IFERROR(VLOOKUP(I17,'CODE H VS CODE ICPE'!$A$2:$D$80,4,FALSE),"") -> Autorisé | X17: =IFERROR(VLOOKUP(J17,'CODE H VS CODE ICPE'!$A$2:$D$80,4,FALSE),"") -> Autorisé | Y17: =IFERROR(VLOOKUP(K17,'CODE H VS CODE ICPE'!$A$2:$D$80,4,FALSE),"") | Z17: =IFERROR(VLOOKUP(L17,'CODE H VS CODE ICPE'!$A$2:$D$80,4,FALSE),"") | AA17: =IFERROR(VLOOKUP(M17,'CODE H VS CODE ICPE'!$A$2:$D$80,4,FALSE),"") | ... AG17: =IFERROR(VLOOKUP(S17,'CODE H VS CODE ICPE'!$A$2:$D$80,4,FALSE),"") | AH17: =IF(COUNTIF(T17:AG17, "Rejected") > 0, "Rejected", IF(COUNTIF(T17:AG17, "Under request") > 0, "Under request", "Accepted")) -> Accepted | AI17: =IF(T17="",0,IF(T17="Interdit",0,VLOOKUP(F17,'CODE H VS CODE ICPE'!$A$2:$E$80,5,FALSE))) -> 99999.99 | AJ17: =IF(U17="",0,IF(U17="Interdit",0,VLOOKUP(G17,'CODE H VS CODE ICPE'!$A$2:$E$80,5,FALSE))) -> 99999.99 | AK17: =IF(V17="",0,IF(V17="Interdit",0,VLOOKUP(H17,'CODE H VS CODE ICPE'!$A$2:$E$80,5,FALSE))) -> 149999.99 | AL17: =IF(W17="",0,IF(W17="Interdit",0,VLOOKUP(I17,'CODE H VS CODE ICPE'!$A$2:$E$80,5,FALSE))) -> 99999.99 | AM17: =IF(X17="",0,IF(X17="Interdit",0,VLOOKUP(J17,'CODE H VS CODE ICPE'!$A$2:$E$80,5,FALSE))) -> 99999.99 | AN17: =IF(Y17="",0,IF(Y17="Interdit",0,VLOOKUP(K17,'CODE H VS CODE ICPE'!$A$2:$E$80,5,FALSE))) -> 0 | AO17: =IF(Z17="",0,IF(Z17="Interdit",0,VLOOKUP(L17,'CODE H VS CODE ICPE'!$A$2:$E$80,5,FALSE))) -> 0 | AP17: =IF(AA17="",0,IF(AA17="Interdit",0,VLOOKUP(M17,'CODE H VS CODE ICPE'!$A$2:$E$80,5,FALSE))) -> 0 | ... AV17: =IF(AG17="",0,IF(AG17="Interdit",0,VLOOKUP(S17,'CODE H VS CODE ICPE'!$A$2:$E$80,5,FALSE))) -> 0 | AW17: =ADDRESS(2,MATCH(MAX(AI17:AV17),AI17:AV17,0)+COLUMN(AI17)-1) -> $AK$2 | AX17: =IF(AH17="Interdit","",IF(AW17="$AI$2",AI17,IF(AW17="$AJ$2",AJ17,IF(AW17="$AK$2",AK17,IF(AW17="$AL$2",AL17,IF(AW17="$AM$2",AM17,IF(AW17="$AN$2",AN17,IF(AW17="$AO$2",AO17,IF(AW17="$AP$2",AP17,IF(AW17="$AQ$2",AQ17,IF(AW17="$AR$2",AR17,IF(AW17="$AS$2",AS17,IF(AW17="$AT$2",AT17,IF(AW17="$AU$2",AU17,IF(AW17="$AV$2",AV17,""))))))))))))))) -> 149999.99 | AY17: =IF(AX17="","",IF(AW17="$AI$2",F17,IF(AW17="$AJ$2",G17,IF(AW17="$AK$2",H17,IF(AW17="$AL$2",I17,IF(AW17="$AM$2",J17,IF(AW17="$AN$2",K17,IF(AW17="$AO$2",L17,IF(AW17="$AP$2",M17,IF(AW17="$AQ$2",N17,IF(AW17="$AR$2",O17,IF(AW17="$AS$2",P17,IF(AW17="$AT$2",Q17,IF(AW17="$AU$2",R17,IF(AW17="$AV$2",S17,""))))))))))))))) -> H314 | AZ17: =IF(AY17="","",IF(AY17=0,"",VLOOKUP(AY17,'CODE H VS CODE ICPE'!$A$1:$E$80,3,FALSE))) -> 4320
A18: 1161 | B18: CARBONATE DE MÉTHYLE | C18: 3 | D18: F1 | E18: DIMETHYL CARBONATE | F18: H225 | T18: =IFERROR(VLOOKUP(F18,'CODE H VS CODE ICPE'!$A$2:$D$80,4,FALSE),"") -> Autorisé | U18: =IFERROR(VLOOKUP(G18,'CODE H VS CODE ICPE'!$A$2:$D$80,4,FALSE),"") | V18: =IFERROR(VLOOKUP(H18,'CODE H VS CODE ICPE'!$A$2:$D$80,4,FALSE),"") | W18: =IFERROR(VLOOKUP(I18,'CODE H VS CODE ICPE'!$A$2:$D$80,4,FALSE),"") | X18: =IFERROR(VLOOKUP(J18,'CODE H VS CODE ICPE'!$A$2:$D$80,4,FALSE),"") | Y18: =IFERROR(VLOOKUP(K18,'CODE H VS CODE ICPE'!$A$2:$D$80,4,FALSE),"") | Z18: =IFERROR(VLOOKUP(L18,'CODE H VS CODE ICPE'!$A$2:$D$80,4,FALSE),"") | AA18: =IFERROR(VLOOKUP(M18,'CODE H VS CODE ICPE'!$A$2:$D$80,4,FALSE),"") | ... AG18: =IFERROR(VLOOKUP(S18,'CODE H VS CODE ICPE'!$A$2:$D$80,4,FALSE),"") | AH18: =IF(COUNTIF(T18:AG18, "Rejected") > 0, "Rejected", IF(COUNTIF(T18:AG18, "Under request") > 0, "Under request", "Accepted")) -> Accepted | AI18: =IF(T18="",0,IF(T18="Interdit",0,VLOOKUP(F18,'CODE H VS CODE ICPE'!$A$2:$E$80,5,FALSE))) -> 99999.99 | AJ18: =IF(U18="",0,IF(U18="Interdit",0,VLOOKUP(G18,'CODE H VS CODE ICPE'!$A$2:$E$80,5,FALSE))) -> 0 | AK18: =IF(V18="",0,IF(V18="Interdit",0,VLOOKUP(H18,'CODE H VS CODE ICPE'!$A$2:$E$80,5,FALSE))) -> 0 | AL18: =IF(W18="",0,IF(W18="Interdit",0,VLOOKUP(I18,'CODE H VS CODE ICPE'!$A$2:$E$80,5,FALSE))) -> 0 | AM18: =IF(X18="",0,IF(X18="Interdit",0,VLOOKUP(J18,'CODE H VS CODE ICPE'!$A$2:$E$80,5,FALSE))) -> 0 | AN18: =IF(Y18="",0,IF(Y18="Interdit",0,VLOOKUP(K18,'CODE H VS CODE ICPE'!$A$2:$E$80,5,FALSE))) -> 0 | AO18: =IF(Z18="",0,IF(Z18="Interdit",0,VLOOKUP(L18,'CODE H VS CODE ICPE'!$A$2:$E$80,5,FALSE))) -> 0 | AP18: =IF(AA18="",0,IF(AA18="Interdit",0,VLOOKUP(M18,'CODE H VS CODE ICPE'!$A$2:$E$80,5,FALSE))) -> 0 | ... AV18: =IF(AG18="",0,IF(AG18="Interdit",0,VLOOKUP(S18,'CODE H VS CODE ICPE'!$A$2:$E$80,5,FALSE))) -> 0 | AW18: =ADDRESS(2,MATCH(MAX(AI18:AV18),AI18:AV18,0)+COLUMN(AI18)-1) -> $AI$2 | AX18: =IF(AH18="Interdit","",IF(AW18="$AI$2",AI18,IF(AW18="$AJ$2",AJ18,IF(AW18="$AK$2",AK18,IF(AW18="$AL$2",AL18,IF(AW18="$AM$2",AM18,IF(AW18="$AN$2",AN18,IF(AW18="$AO$2",AO18,IF(AW18="$AP$2",AP18,IF(AW18="$AQ$2",AQ18,IF(AW18="$AR$2",AR18,IF(AW18="$AS$2",AS18,IF(AW18="$AT$2",AT18,IF(AW18="$AU$2",AU18,IF(AW18="$AV$2",AV18,""))))))))))))))) -> 99999.99 | AY18: =IF(AX18="","",IF(AW18="$AI$2",F18,IF(AW18="$AJ$2",G18,IF(AW18="$AK$2",H18,IF(AW18="$AL$2",I18,IF(AW18="$AM$2",J18,IF(AW18="$AN$2",K18,IF(AW18="$AO$2",L18,IF(AW18="$AP$2",M18,IF(AW18="$AQ$2",N18,IF(AW18="$AR$2",O18,IF(AW18="$AS$2",P18,IF(AW18="$AT$2",Q18,IF(AW18="$AU$2",R18,IF(AW18="$AV$2",S18,""))))))))))))))) -> H225 | AZ18: =IF(AY18="","",IF(AY18=0,"",VLOOKUP(AY18,'CODE H VS CODE ICPE'!$A$1:$E$80,3,FALSE))) -> 4331
A19: 1164 | B19: SULFURE DE MÉTHYLE | C19: 3 | D19: F1 | E19: DIMETHYL SULPHIDE | F19: H225 | G19: H319 | T19: =IFERROR(VLOOKUP(F19,'CODE H VS CODE ICPE'!$A$2:$D$80,4,FALSE),"") -> Autorisé | U19: =IFERROR(VLOOKUP(G19,'CODE H VS CODE ICPE'!$A$2:$D$80,4,FALSE),"") -> Autorisé | V19: =IFERROR(VLOOKUP(H19,'CODE H VS CODE ICPE'!$A$2:$D$80,4,FALSE),"") | W19: =IFERROR(VLOOKUP(I19,'CODE H VS CODE ICPE'!$A$2:$D$80,4,FALSE),"") | X19: =IFERROR(VLOOKUP(J19,'CODE H VS CODE ICPE'!$A$2:$D$80,4,FALSE),"") | Y19: =IFERROR(VLOOKUP(K19,'CODE H VS CODE ICPE'!$A$2:$D$80,4,FALSE),"") | Z19: =IFERROR(VLOOKUP(L19,'CODE H VS CODE ICPE'!$A$2:$D$80,4,FALSE),"") | AA19: =IFERROR(VLOOKUP(M19,'CODE H VS CODE ICPE'!$A$2:$D$80,4,FALSE),"") | ... AG19: =IFERROR(VLOOKUP(S19,'CODE H VS CODE ICPE'!$A$2:$D$80,4,FALSE),"") | AH19: =IF(COUNTIF(T19:AG19, "Rejected") > 0, "Rejected", IF(COUNTIF(T19:AG19, "Under request") > 0, "Under request", "Accepted")) -> Accepted | AI19: =IF(T19="",0,IF(T19="Interdit",0,VLOOKUP(F19,'CODE H VS CODE ICPE'!$A$2:$E$80,5,FALSE))) -> 99999.99 | AJ19: =IF(U19="",0,IF(U19="Interdit",0,VLOOKUP(G19,'CODE H VS CODE ICPE'!$A$2:$E$80,5,FALSE))) -> 99999.99 | AK19: =IF(V19="",0,IF(V19="Interdit",0,VLOOKUP(H19,'CODE H VS CODE ICPE'!$A$2:$E$80,5,FALSE))) -> 0 | AL19: =IF(W19="",0,IF(W19="Interdit",0,VLOOKUP(I19,'CODE H VS CODE ICPE'!$A$2:$E$80,5,FALSE))) -> 0 | AM19: =IF(X19="",0,IF(X19="Interdit",0,VLOOKUP(J19,'CODE H VS CODE ICPE'!$A$2:$E$80,5,FALSE))) -> 0 | AN19: =IF(Y19="",0,IF(Y19="Interdit",0,VLOOKUP(K19,'CODE H VS CODE ICPE'!$A$2:$E$80,5,FALSE))) -> 0 | AO19: =IF(Z19="",0,IF(Z19="Interdit",0,VLOOKUP(L19,'CODE H VS CODE ICPE'!$A$2:$E$80,5,FALSE))) -> 0 | AP19: =IF(AA19="",0,IF(AA19="Interdit",0,VLOOKUP(M19,'CODE H VS CODE ICPE'!$A$2:$E$80,5,FALSE))) -> 0 | ... AV19: =IF(AG19="",0,IF(AG19="Interdit",0,VLOOKUP(S19,'CODE H VS CODE ICPE'!$A$2:$E$80,5,FALSE))) -> 0 | AW19: =ADDRESS(2,MATCH(MAX(AI19:AV19),AI19:AV19,0)+COLUMN(AI19)-1) -> $AI$2 | AX19: =IF(AH19="Interdit","",IF(AW19="$AI$2",AI19,IF(AW19="$AJ$2",AJ19,IF(AW19="$AK$2",AK19,IF(AW19="$AL$2",AL19,IF(AW19="$AM$2",AM19,IF(AW19="$AN$2",AN19,IF(AW19="$AO$2",AO19,IF(AW19="$AP$2",AP19,IF(AW19="$AQ$2",AQ19,IF(AW19="$AR$2",AR19,IF(AW19="$AS$2",AS19,IF(AW19="$AT$2",AT19,IF(AW19="$AU$2",AU19,IF(AW19="$AV$2",AV19,""))))))))))))))) -> 99999.99 | AY19: =IF(AX19="","",IF(AW19="$AI$2",F19,IF(AW19="$AJ$2",G19,IF(AW19="$AK$2",H19,IF(AW19="$AL$2",I19,IF(AW19="$AM$2",J19,IF(AW19="$AN$2",K19,IF(AW19="$AO$2",L19,IF(AW19="$AP$2",M19,IF(AW19="$AQ$2",N19,IF(AW19="$AR$2",O19,IF(AW19="$AS$2",P19,IF(AW19="$AT$2",Q19,IF(AW19="$AU$2",R19,IF(AW19="$AV$2",S19,""))))))))))))))) -> H225 | AZ19: =IF(AY19="","",IF(AY19=0,"",VLOOKUP(AY19,'CODE H VS CODE ICPE'!$A$1:$E$80,3,FALSE))) -> 4331
A20: 1166 | B20: DIOXOLANNE | C20: 3 | D20: F1 | E20: DIOXOLANE | F20: H225 | T20: =IFERROR(VLOOKUP(F20,'CODE H VS CODE ICPE'!$A$2:$D$80,4,FALSE),"") -> Autorisé | U20: =IFERROR(VLOOKUP(G20,'CODE H VS CODE ICPE'!$A$2:$D$80,4,FALSE),"") | V20: =IFERROR(VLOOKUP(H20,'CODE H VS CODE ICPE'!$A$2:$D$80,4,FALSE),"") | W20: =IFERROR(VLOOKUP(I20,'CODE H VS CODE ICPE'!$A$2:$D$80,4,FALSE),"") | X20: =IFERROR(VLOOKUP(J20,'CODE H VS CODE ICPE'!$A$2:$D$80,4,FALSE),"") | Y20: =IFERROR(VLOOKUP(K20,'CODE H VS CODE ICPE'!$A$2:$D$80,4,FALSE),"") | Z20: =IFERROR(VLOOKUP(L20,'CODE H VS CODE ICPE'!$A$2:$D$80,4,FALSE),"") | AA20: =IFERROR(VLOOKUP(M20,'CODE H VS CODE ICPE'!$A$2:$D$80,4,FALSE),"") | ... AG20: =IFERROR(VLOOKUP(S20,'CODE H VS CODE ICPE'!$A$2:$D$80,4,FALSE),"") | AH20: =IF(COUNTIF(T20:AG20, "Rejected") > 0, "Rejected", IF(COUNTIF(T20:AG20, "Under request") > 0, "Under request", "Accepted")) -> Accepted | AI20: =IF(T20="",0,IF(T20="Interdit",0,VLOOKUP(F20,'CODE H VS CODE ICPE'!$A$2:$E$80,5,FALSE))) -> 99999.99 | AJ20: =IF(U20="",0,IF(U20="Interdit",0,VLOOKUP(G20,'CODE H VS CODE ICPE'!$A$2:$E$80,5,FALSE))) -> 0 | AK20: =IF(V20="",0,IF(V20="Interdit",0,VLOOKUP(H20,'CODE H VS CODE ICPE'!$A$2:$E$80,5,FALSE))) -> 0 | AL20: =IF(W20="",0,IF(W20="Interdit",0,VLOOKUP(I20,'CODE H VS CODE ICPE'!$A$2:$E$80,5,FALSE))) -> 0 | AM20: =IF(X20="",0,IF(X20="Interdit",0,VLOOKUP(J20,'CODE H VS CODE ICPE'!$A$2:$E$80,5,FALSE))) -> 0 | AN20: =IF(Y20="",0,IF(Y20="Interdit",0,VLOOKUP(K20,'CODE H VS CODE ICPE'!$A$2:$E$80,5,FALSE))) -> 0 | AO20: =IF(Z20="",0,IF(Z20="Interdit",0,VLOOKUP(L20,'CODE H VS CODE ICPE'!$A$2:$E$80,5,FALSE))) -> 0 | AP20: =IF(AA20="",0,IF(AA20="Interdit",0,VLOOKUP(M20,'CODE H VS CODE ICPE'!$A$2:$E$80,5,FALSE))) -> 0 | ... AV20: =IF(AG20="",0,IF(AG20="Interdit",0,VLOOKUP(S20,'CODE H VS CODE ICPE'!$A$2:$E$80,5,FALSE))) -> 0 | AW20: =ADDRESS(2,MATCH(MAX(AI20:AV20),AI20:AV20,0)+COLUMN(AI20)-1) -> $AI$2 | AX20: =IF(AH20="Interdit","",IF(AW20="$AI$2",AI20,IF(AW20="$AJ$2",AJ20,IF(AW20="$AK$2",AK20,IF(AW20="$AL$2",AL20,IF(AW20="$AM$2",AM20,IF(AW20="$AN$2",AN20,IF(AW20="$AO$2",AO20,IF(AW20="$AP$2",AP20,IF(AW20="$AQ$2",AQ20,IF(AW20="$AR$2",AR20,IF(AW20="$AS$2",AS20,IF(AW20="$AT$2",AT20,IF(AW20="$AU$2",AU20,IF(AW20="$AV$2",AV20,""))))))))))))))) -> 99999.99 | AY20: =IF(AX20="","",IF(AW20="$AI$2",F20,IF(AW20="$AJ$2",G20,IF(AW20="$AK$2",H20,IF(AW20="$AL$2",I20,IF(AW20="$AM$2",J20,IF(AW20="$AN$2",K20,IF(AW20="$AO$2",L20,IF(AW20="$AP$2",M20,IF(AW20="$AQ$2",N20,IF(AW20="$AR$2",O20,IF(AW20="$AS$2",P20,IF(AW20="$AT$2",Q20,IF(AW20="$AU$2",R20,IF(AW20="$AV$2",S20,""))))))))))))))) -> H225 | AZ20: =IF(AY20="","",IF(AY20=0,"",VLOOKUP(AY20,'CODE H VS CODE ICPE'!$A$1:$E$80,3,FALSE))) -> 4331
A21: 1167 | B21: ÉTHER VINYLIQUE STABILISÉ | C21: 3 | D21: F1 | E21: DIVINYL ETHER, STABILIZED | F21: H225 | G21: H336 | H21: H412 | T21: =IFERROR(VLOOKUP(F21,'CODE H VS CODE ICPE'!$A$2:$D$80,4,FALSE),"") -> Autorisé | U21: =IFERROR(VLOOKUP(G21,'CODE H VS CODE ICPE'!$A$2:$D$80,4,FALSE),"") -> Autorisé | V21: =IFERROR(VLOOKUP(H21,'CODE H VS CODE ICPE'!$A$2:$D$80,4,FALSE),"") -> Autorisé | W21: =IFERROR(VLOOKUP(I21,'CODE H VS CODE ICPE'!$A$2:$D$80,4,FALSE),"") | X21: =IFERROR(VLOOKUP(J21,'CODE H VS CODE ICPE'!$A$2:$D$80,4,FALSE),"") | Y21: =IFERROR(VLOOKUP(K21,'CODE H VS CODE ICPE'!$A$2:$D$80,4,FALSE),"") | Z21: =IFERROR(VLOOKUP(L21,'CODE H VS CODE ICPE'!$A$2:$D$80,4,FALSE),"") | AA21: =IFERROR(VLOOKUP(M21,'CODE H VS CODE ICPE'!$A$2:$D$80,4,FALSE),"") | ... AG21: =IFERROR(VLOOKUP(S21,'CODE H VS CODE ICPE'!$A$2:$D$80,4,FALSE),"") | AH21: =IF(COUNTIF(T21:AG21, "Rejected") > 0, "Rejected", IF(COUNTIF(T21:AG21, "Under request") > 0, "Under request", "Accepted")) -> Accepted | AI21: =IF(T21="",0,IF(T21="Interdit",0,VLOOKUP(F21,'CODE H VS CODE ICPE'!$A$2:$E$80,5,FALSE))) -> 99999.99 | AJ21: =IF(U21="",0,IF(U21="Interdit",0,VLOOKUP(G21,'CODE H VS CODE ICPE'!$A$2:$E$80,5,FALSE))) -> 99999.99 | AK21: =IF(V21="",0,IF(V21="Interdit",0,VLOOKUP(H21,'CODE H VS CODE ICPE'!$A$2:$E$80,5,FALSE))) -> 99999.99 | AL21: =IF(W21="",0,IF(W21="Interdit",0,VLOOKUP(I21,'CODE H VS CODE ICPE'!$A$2:$E$80,5,FALSE))) -> 0 | AM21: =IF(X21="",0,IF(X21="Interdit",0,VLOOKUP(J21,'CODE H VS CODE ICPE'!$A$2:$E$80,5,FALSE))) -> 0 | AN21: =IF(Y21="",0,IF(Y21="Interdit",0,VLOOKUP(K21,'CODE H VS CODE ICPE'!$A$2:$E$80,5,FALSE))) -> 0 | AO21: =IF(Z21="",0,IF(Z21="Interdit",0,VLOOKUP(L21,'CODE H VS CODE ICPE'!$A$2:$E$80,5,FALSE))) -> 0 | AP21: =IF(AA21="",0,IF(AA21="Interdit",0,VLOOKUP(M21,'CODE H VS CODE ICPE'!$A$2:$E$80,5,FALSE))) -> 0 | ... AV21: =IF(AG21="",0,IF(AG21="Interdit",0,VLOOKUP(S21,'CODE H VS CODE ICPE'!$A$2:$E$80,5,FALSE))) -> 0 | AW21: =ADDRESS(2,MATCH(MAX(AI21:AV21),AI21:AV21,0)+COLUMN(AI21)-1) -> $AI$2 | AX21: =IF(AH21="Interdit","",IF(AW21="$AI$2",AI21,IF(AW21="$AJ$2",AJ21,IF(AW21="$AK$2",AK21,IF(AW21="$AL$2",AL21,IF(AW21="$AM$2",AM21,IF(AW21="$AN$2",AN21,IF(AW21="$AO$2",AO21,IF(AW21="$AP$2",AP21,IF(AW21="$AQ$2",AQ21,IF(AW21="$AR$2",AR21,IF(AW21="$AS$2",AS21,IF(AW21="$AT$2",AT21,IF(AW21="$AU$2",AU21,IF(AW21="$AV$2",AV21,""))))))))))))))) -> 99999.99 | AY21: =IF(AX21="","",IF(AW21="$AI$2",F21,IF(AW21="$AJ$2",G21,IF(AW21="$AK$2",H21,IF(AW21="$AL$2",I21,IF(AW21="$AM$2",J21,IF(AW21="$AN$2",K21,IF(AW21="$AO$2",L21,IF(AW21="$AP$2",M21,IF(AW21="$AQ$2",N21,IF(AW21="$AR$2",O21,IF(AW21="$AS$2",P21,IF(AW21="$AT$2",Q21,IF(AW21="$AU$2",R21,IF(AW21="$AV$2",S21,""))))))))))))))) -> H225 | AZ21: =IF(AY21="","",IF(AY21=0,"",VLOOKUP(AY21,'CODE H VS CODE ICPE'!$A$1:$E$80,3,FALSE))) -> 4331
